Workbook

Sheet Summary
A1: Rabobank Australia | T1: BD Costs - Questions
A2: FBT return for the year ended 31 March 2025 | T2: Q1 | U2: Isn't it that under Div9A all meals provided to clients irrespective of amount, time or where is not “sustenance”, but entertaiment.
A3: WP2 - Entertainment sensitive GL Accounts for Apr 2024 to Dec 2024 | E3: Tfrred to "WPE1 ME Summary - GL analysis ent accounts" | T3: Q2 | U3: Totally agree, sounds capital and not on rev acct.
F4: =F29 -> 143205.39 | P4: =P29 -> 470911.71 | Q4: =Q29 -> 8576.02
P5: Income tax purposes
A6: Account# | B6: Account Description | D6: Tax Description | E6: ME? Y/N | F6: ME $ | G6: AU001 / MEC | H6: AU052 | I6: Not ME but other type of FB Y/N | J6: Not ME but other type of FB ==> $ | K6: Nets to Nil in GL accts | L6: s58P M&I or Bus Exp - notFB | M6: ME | N6: Car FB - addn op costs | O6: CP Exp FB | P6: Capital expenditure | Q6: No FBT and not ded | S6: Prepared by | T6: Date | U6: Reviewer Queries | V6: Date
A8: 5140001000 | B8: Training expenses | D8: Picked up in Tuition expese analysis - NFA
A9: 5140001010 | B9: External Training and Seminars | D9: Minor ME amounts | E9: Y | F9: ='Ext Training'!V2+'Ext Training'!V3 -> 772.72 | G9: ='Ext Training'!V2 -> 0 | H9: ='Ext Training'!V3 -> 772.72 | I9: ='Ext Training'!W53 -> 0 | J9: ='Ext Training'!X53 -> 0 | K9: ='Ext Training'!Y53 -> 0 | L9: ='Ext Training'!Z53 -> 0 | M9: ='Ext Training'!AA53 -> 0 | N9: ='Ext Training'!AB53 -> 0 | O9: ='Ext Training'!AC53 -> 0 | P9: ='Ext Training'!AF53 -> 0 | Q9: ='Ext Training'!AG53 -> 0 | U9: OK
A10: 5140001030 | B10: Training travel and lodging ex | D10: Minor ME amounts | E10: Y | F10: ='Training Travel&lodging'!V4+'Training Travel&lodging'!V5 -> 35.88 | G10: ='Training Travel&lodging'!V4 -> 0 | H10: ='Training Travel&lodging'!V5 -> 35.88 | U10: OK
A11: 5160001000 | B11: Publicity/advertising | D11: No ME included. Minor cap amounts | E11: N | F11: ='Publicity&Advertising'!U3+'Publicity&Advertising'!U4 -> 1413.94 | G11: ='Publicity&Advertising'!U3 -> 1413.94 | H11: ='Publicity&Advertising'!U4 -> 0 | P11: ='Publicity&Advertising'!AC3+'Publicity&Advertising'!AC4 -> 426.45 | Q11: ='Publicity&Advertising'!AD3+'Publicity&Advertising'!AD4 -> 0 | U11: Noted
A12: 5160006000 | B12: Opening jubilees own buildin | D12: No ME included. All tax deductible | E12: N | F12: ='Opening Jubilees'!S4+'Opening Jubilees'!S5 -> 0 | G12: ='Opening Jubilees'!S4 -> 0 | H12: ='Opening Jubilees'!S5 -> 0 | U12: Noted
A13: 5160007000 | B13: Sponsoring | D13: No ME included. All tax deductible | E13: N | F13: =Sponsoring!U2+Sponsoring!U3 -> 0 | G13: =Sponsoring!U2 -> 0 | H13: =Sponsoring!U3 -> 0 | P13: =Sponsoring!AC2+Sponsoring!AC3 -> 0 | Q13: =Sponsoring!AD2+Sponsoring!AD3 -> 407.73 | U13: Noted
A14: 5160008000 | B14: Promotional gifts | D14: No ME included. Staff gifts are exempt from FBT | E14: N | F14: ='Promotional gifts'!U4+'Promotional gifts'!U5 -> 0 | G14: ='Promotional gifts'!U4 -> 0 | H14: ='Promotional gifts'!U5 -> 0 | U14: Noted
A15: 5160010000 | B15: Marketing expense | D15: Includes meal entertainment subject to FBT using 50/50 method | E15: Y | F15: ='Marketing exp'!V2+'Marketing exp'!V3 -> 6742.26 | G15: ='Marketing exp'!V2 -> 2454.37 | H15: ='Marketing exp'!V3 -> 4287.89 | I15: ='Marketing exp'!W71 -> 0 | J15: ='Marketing exp'!X71 -> 0 | K15: ='Marketing exp'!Y71 -> 0 | L15: ='Marketing exp'!Z71 -> 0 | M15: ='Marketing exp'!AA71 -> 0 | N15: ='Marketing exp'!AB71 -> 0 | O15: ='Marketing exp'!AC71 -> 0 | P15: ='Marketing exp'!AF71 -> 0 | Q15: ='Marketing exp'!AG71 -> 0 | U15: OK
A16: 5160011000 | B16: Business development | D16: Includes ME and recreation expenses not deductible | E16: Y | F16: ='Business Dev'!V3+'Business Dev'!V4 -> 111166.4 | G16: ='Business Dev'!V3 -> 32145.58 | H16: ='Business Dev'!V4 -> 79020.82 | I16: ='Business Dev'!W187 -> 0 | J16: ='Business Dev'!X187 -> 0 | K16: ='Business Dev'!Y187 -> 0 | L16: ='Business Dev'!Z187 -> 0 | M16: ='Business Dev'!AA187 -> 0 | N16: ='Business Dev'!AB187 -> 0 | O16: ='Business Dev'!AC187 -> 0 | P16: ='Business Dev'!AD3+'Business Dev'!AD4 -> 464087.57 | Q16: ='Business Dev'!AE3+'Business Dev'!AE4 -> 415.15 | U16: See 2 Qs above
A17: 5160999000 | B17: Public relations | D17: No ME included. All tax deductible | E17: N | F17: ='Public relations'!V4+'Public relations'!V5 -> 240.1 | G17: ='Public relations'!V4 -> 230.77 | H17: ='Public relations'!V5 -> 9.33 | P17: ='Public relations'!AD3+'Public relations'!AD4 -> 0 | Q17: ='Public relations'!AE3+'Public relations'!AE4 -> 0 | U17: OK
A18: 5180003000 | B18: Advice Tax & Legal expenses | D18: Picked up in Invoices WPE3 expese analysis - NFA | E18: N | U18: OK
A19: 5190001000 | B19: Contributions& club membership | D19: No ME included. All tax deductible | E19: N | F19: =Membership!V3+Membership!V4 -> 0 | G19: =Membership!V3 -> 0 | H19: =Membership!V4 -> 0 | P19: =Membership!AD3+Membership!AD4 -> 0 | Q19: =Membership!AE3+Membership!AE4 -> 352.15 | U19: OK
A20: 5200006000 | B20: Meeting costs | D20: Includes meal entertainment subject to FBT using 50/50 method | E20: Y | F20: ='Meeting costs'!V8 -> 16912.95 | G20: ='Meeting costs'!V6 -> 8362.5 | H20: ='Meeting costs'!V7 -> 8550.45 | P20: ='Meeting costs'!AD6+'Meeting costs'!AD7 -> 0 | Q20: ='Meeting costs'!AE6+'Meeting costs'!AE7 -> 1268.18 | U20: Q on Client sustenance?
A21: 5200999000 | B21: Miscellaneous expenses | D21: No ME included. Check sustainability payment | E21: N | G21: ='Misc exp'!U4 -> 0 | H21: ='Misc exp'!U5 -> 0 | U21: One amount for sustainability benefit. Check against HR report
A22: 5200999010 | B22: Sundry expenses | D22: Includes meal entertainment subject to FBT using 50/50 method | E22: Y | F22: ='Sundry exp'!V4+'Sundry exp'!V5 -> 239.17 | G22: ='Sundry exp'!V4 -> 0 | H22: ='Sundry exp'!V5 -> 239.17 | I22: ='Sundry exp'!W34 -> 0 | J22: ='Sundry exp'!X34 -> 0 | K22: ='Sundry exp'!Y34 -> 0 | L22: ='Sundry exp'!Z34 -> 0 | M22: ='Sundry exp'!AA34 -> 0 | N22: ='Sundry exp'!AB34 -> 0 | O22: ='Sundry exp'!AC34 -> 0 | P22: ='Sundry exp'!AD34 -> 0 | Q22: ='Sundry exp'!AE34 -> 0 | U22: OK
A23: 5200999020 | B23: Miscellaneous expenses (2) - Tours | D23: Inlcudes ME and staff gifts which are exempt from FBT | E23: Y | F23: ='Misc exp (2)'!V173 -> 0 | G23: ='Misc exp (2)'!V6 -> 0 | H23: ='Misc exp (2)'!V7 -> 0 | I23: ='Misc exp (2)'!W173 -> 0 | J23: ='Misc exp (2)'!X173 -> 0 | K23: ='Misc exp (2)'!Y173 -> 0 | L23: ='Misc exp (2)'!Z173 -> 0 | M23: ='Misc exp (2)'!AA173 -> 0 | N23: ='Misc exp (2)'!AB173 -> 0 | O23: ='Misc exp (2)'!AC173 -> 0 | P23: ='Misc exp (2)'!AD4+'Misc exp (2)'!AD5 -> 1248.37 | Q23: ='Misc exp (2)'!AE4+'Misc exp (2)'!AE5 -> 275.56 | U23: OK
A24: 5900050000 | B24: Other non banking expenses | D24: No ME included. All tax deductible | E24: N | F24: ='Other non-bank exp'!U4+'Other non-bank exp'!U5 -> 0 | G24: ='Other non-bank exp'!U4 -> 0 | H24: ='Other non-bank exp'!U5 -> 0 | U24: OK
A25: 5100999000 | B25: Other office expenses | D25: Inlcudes ME, staff gifts which are exempt from FBT and capital expenditure | E25: Y | F25: ='Other exp'!U3+'Other exp'!U4 -> 5241.79 | G25: ='Other exp'!U3 -> 0 | H25: ='Other exp'!U4 -> 5241.79 | I25: ='Other exp'!V312 -> 0 | J25: ='Other exp'!W312 -> 0 | K25: ='Other exp'!X312 -> 0 | L25: ='Other exp'!Y312 -> 0 | M25: ='Other exp'!Z312 -> 0 | N25: ='Other exp'!AA312 -> 0 | O25: ='Other exp'!AB312 -> 0 | P25: ='Other exp'!AC3+'Other exp'!AC4 -> 5149.32 | Q25: ='Other exp'!AD3+'Other exp'!AD4 -> 5401.83 | U25: OK
A26: 5190002000 | B26: Donations | D26: ME and cap | E26: Y | F26: =Donations!V3+Donations!V4 -> 440.18 | G26: =Donations!V3 -> 0 | H26: =Donations!V4 -> 440.18 | P26: =Donations!AD4+Donations!AD3 -> 0 | Q26: =Donations!AE4+Donations!AE3 -> 455.42 | U26: OK
A27: 5160002000 | B27: Client periodicals/magazines | D27: No ME | E27: N | U27: OK
D29: Total | F29: =SUM(F7:F28) -> 143205.39 | G29: =SUM(G8:G25) -> 44607.16 | H29: =SUM(H8:H25) -> 98158.05 | I29: =SUM(I7:I28) -> 0 | J29: =SUM(J7:J28) -> 0 | K29: =SUM(K7:K28) -> 0 | L29: =SUM(L7:L28) -> 0 | M29: =SUM(M7:M28) -> 0 | N29: =SUM(N7:N28) -> 0 | O29: =SUM(O7:O28) -> 0 | P29: =SUM(P7:P28) -> 470911.71 | Q29: =SUM(Q7:Q28) -> 8576.02
U30: LF: Queries dealt with and responses at WPE1. Largely agreed with questions raises but have not made major changes given stage of process. Agreed we need a separate GL account or something for food whilst travelling | V30: LF response to my queries noted and accept calc accordingly. AJL16/5
O31: AU001 Split | P31: 0 | Q31: =Sponsoring!AD2 -> 0
O32: AU052 split | P32: 0 | Q32: =Sponsoring!AD3+'Business Dev'!AE4+Membership!AE4+'Meeting costs'!AE7+'Misc exp (2)'!AE5+'Other exp'!AD4+Donations!AE4 -> 8576.02
Q33: =SUM(Q31:Q32) -> 8576.02

Sheet Ext Training
A1: Account Number | C1: =Summary!A9 -> 5140001010
A2: Account Name | C2: =Summary!B9 -> External Training and Seminars | H2: Notes: | T2: AU001 | V2: =SUMIF($A$10:$A$23974,"AU001",V9:V23973) -> 0 | AC2: AU001 | AD2: =SUMIF($A$10:$A$23974,"AU001",AD9:AD23973) -> 0
A3: GL Total | C3: 507940.78 | H3: Expenditure on university courses and other courses conferences attended by employees. These are not considered REAP but are in | T3: AU052 | V3: =SUMIF($A$10:$A$23975,"AU052",V9:V23974) -> 772.72 | AC3: AU052 | AD3: =SUMIF($A$10:$A$23975,"AU052",AD9:AD23974) -> 0
A4: Per TB | C4: =SUM(E:E) -> 507940.78 | H4: relation to the employees current roles so would be otherwise deductible for income tax purposes. No FBT will apply to these expenses. | AE4: =SUMIF($A$10:$A$23974,"AU001",AE9:AE23973) -> 0
A5: Variance | C5: =C3-C4 -> 0 | AE5: =SUMIF($A$10:$A$23975,"AU052",AE9:AE23974) -> 0
AD6: Income tax purposes
A7: BUSINESS_UNIT_CODE | B7: OPERATING_UNIT_CODE | C7: ACCOUNT_CODE | D7: DESCRIPTION | E7: BASE_AMOUNT | F7: BASE_CURRENCY_CODE | G7: JOURNAL_DATE | H7: DESCR | I7: LINE_DESCR | J7: PURPOSE | K7: INVOICE_DESCR | L7: INVOICE_ID | M7: VENDOR_NAME | N7: EMPLOYEE_NAME | O7: CHARGE_DESCRIPTION | Q7: ABS | R7: Search Terms | S7: Tax Description | T7: ME? Y/N | U7: OU | V7: ME $ | W7: Not ME but other type of FB Y/N | X7: Not ME but other type of FB ==> $ | Y7: Nets to Nil in GL accts | Z7: s58P M&I or Bus Exp - notFB | AA7: ME | AB7: Car FB - addn op costs | AC7: CP Exp FB | AD7: Capital expenditure | AE7: No FBT and not ded | AF7: Additional Comments
A8: AU052 | B8: AU010029 | C8: 5140001010 | D8: External Training and Seminars | E8: 55000 | F8: AUQ | G8: 45638 | H8: ADP Monthly Invoice - Dec2024 | I8: Graduate development workshop | Q8: =ABS(E8) -> 55000
A9: AU052 | B9: AU025074 | C9: 5140001010 | D9: External Training and Seminars | E9: 38303.23 | F9: AUQ | G9: 45642 | H9: AP Accruals | I9: FGH3492105120-OERUD00 | K9: Technical Training | L9: FGH3492105120 | M9: ERUDITUS LEARNING SOLUTIONS PTE LTD | Q9: =ABS(E9) -> 38303.23
A10: AU052 | B10: AU010021 | C10: 5140001010 | D10: External Training and Seminars | E10: 25031.11 | F10: AUQ | G10: 45629 | H10: AP Accruals | I10: INV-0198-ASUCC00 | K10: Co-faciliation of PLE M2 & Pre | L10: INV-0198 | M10: SUCCESS2YOU PTY LTD | Q10: =ABS(E10) -> 25031.11
A11: AU001 | B11: AU032054 | C11: 5140001010 | D11: External Training and Seminars | E11: 21682.78 | F11: AUQ | G11: 45597 | H11: AP Accruals | I11: 2024220-AMCEA00 | K11: Development of Nature 101 trai | L11: 2024220 | M11: ECOSYSTEM THINKING | Q11: =ABS(E11) -> 21682.78
A12: AU001 | B12: AU032055 | C12: 5140001010 | D12: External Training and Seminars | E12: 21450 | F12: AUQ | G12: 45413 | H12: AP Accruals | I12: 863320-AUNIV00 | K12: Geraldton CNAg September 2023 | L12: 863320 | M12: THE UNIVERSITY OF MELBOURNE | Q12: =ABS(E12) -> 21450
A13: AU052 | B13: AU025104 | C13: 5140001010 | D13: External Training and Seminars | E13: 12155 | F13: AUQ | G13: 45629 | H13: AP Accruals | I13: INV-20148-AFINA09 | K13: FEP Enrolment costs | L13: INV-20148 | M13: FINANCIAL EDUCATION PROFFESIONALS PTYLTD | Q13: =ABS(E13) -> 12155
A14: AU001 | B14: AU032055 | C14: 5140001010 | D14: External Training and Seminars | E14: 11022.78 | F14: AUQ | G14: 45467 | H14: AP Accruals | I14: 863376-AUNIV00 | L14: 863376 | M14: THE UNIVERSITY OF MELBOURNE | Q14: =ABS(E14) -> 11022.78
A15: AU052 | B15: AU010030 | C15: 5140001010 | D15: External Training and Seminars | E15: 10468.94 | F15: AUQ | G15: 45488 | H15: AP Accruals | I15: INV-0346-ALEAR00 | K15: IFTI module | L15: INV-0346 | M15: LEARN STUDIOS PTY LTD | Q15: =ABS(E15) -> 10468.94
A16: AU052 | B16: AU073158 | C16: 5140001010 | D16: External Training and Seminars | E16: 8250 | F16: AUQ | G16: 45597 | H16: AP Accruals | I16: INV-7530-AMILA00 | K16: Offsite Training | L16: INV-7530 | M16: MILAN PARTNERS | Q16: =ABS(E16) -> 8250
A17: AU001 | B17: AU032074 | C17: 5140001010 | D17: External Training and Seminars | E17: 7983.47 | F17: AUQ | G17: 45432 | H17: AP Accruals | I17: RAB052-AHUDS00 | K17: HudsonFaciliation_FSW_SVIC.TAS | L17: RAB052 | M17: HUDSON FACILITATION PTY LTD | Q17: =ABS(E17) -> 7983.47
A18: AU052 | B18: AU020016 | C18: 5140001010 | D18: External Training and Seminars | E18: 7630.15 | F18: AUQ | G18: 45580 | H18: AP Accruals | I18: INV-0547-AMADM00 | K18: Leadership training by MAD Min | L18: INV-0547 | M18: MAD MINDWORKS PTY LTD | Q18: =ABS(E18) -> 7630.15
A19: AU001 | B19: AU050115 | C19: 5140001010 | D19: External Training and Seminars | E19: 7559.11 | F19: AUQ | G19: 45475 | H19: AP Accruals | I19: AGSM67775-AUNIV06 | K19: Accelerated Leadership Program | L19: AGSM67775 | M19: UNIVERSITY OF NSW | Q19: =ABS(E19) -> 7559.11
A20: AU001 | B20: AU030055 | C20: 5140001010 | D20: External Training and Seminars | E20: 7557.53 | F20: AUQ | G20: 45475 | H20: AP Accruals | I20: AGSM58206-AUNIV06 | L20: AGSM58206 | M20: UNIVERSITY OF NSW | Q20: =ABS(E20) -> 7557.53
A21: AU001 | B21: AU050119 | C21: 5140001010 | D21: External Training and Seminars | E21: 7523.24 | F21: AUQ | G21: 45505 | H21: AP Accruals | I21: AGSM83092-AUNIV06 | K21: Accelerated Leadership Program | L21: AGSM83092 | M21: UNIVERSITY OF NSW | Q21: =ABS(E21) -> 7523.24
A22: AU052 | B22: AU010021 | C22: 5140001010 | D22: External Training and Seminars | E22: 7485.39 | F22: AUQ | G22: 45566 | H22: AP Accruals | I22: 38247611-19/09/24-AVIEW00 | K22: View By Sydney final deposit | L22: 38247611-19/09/24 | M22: VIEW BY SYDNEY | Q22: =ABS(E22) -> 7485.39
A23: AU001 | B23: AU020080 | C23: 5140001010 | D23: External Training and Seminars | E23: 7368.74 | F23: AUQ | G23: 45579 | H23: AP Accruals | I23: AGSM56780-AUNIV06 | K23: AGSM leadership training | L23: AGSM56780 | M23: UNIVERSITY OF NSW | Q23: =ABS(E23) -> 7368.74
A24: AU001 | B24: AU032074 | C24: 5140001010 | D24: External Training and Seminars | E24: 6541.32 | F24: AUQ | G24: 45425 | H24: AP Accruals | I24: RAB051-AHUDS00 | K24: HudsonFailitation_VirtualFSW_M | L24: RAB051 | M24: HUDSON FACILITATION PTY LTD | Q24: =ABS(E24) -> 6541.32
A25: AU052 | B25: AU020080 | C25: 5140001010 | D25: External Training and Seminars | E25: 6520.8 | F25: AUQ | G25: 45537 | H25: AP Accruals | I25: 11907-A100001 | K25: Half Day Simulation Workshop f | L25: 11907 | M25: 10000 HOURS (AUSTRALIA) PTY LTD | Q25: =ABS(E25) -> 6520.8
A26: AU052 | B26: AU025080 | C26: 5140001010 | D26: External Training and Seminars | E26: 5933.98 | F26: AUQ | G26: 45579 | H26: AP Accruals | I26: INV02157615-OOREI00 | K26: Subscription Renewal | L26: INV02157615 | M26: OREILLY MEDIA INC | Q26: =ABS(E26) -> 5933.98
A27: AU052 | B27: AU025074 | C27: 5140001010 | D27: External Training and Seminars | E27: 5657.3 | F27: AUQ | G27: 45524 | H27: CCMS | I27: KumarA1-Tuition (study) Reimbu | J27: Training | M27: ALC TRAINING | Q27: =ABS(E27) -> 5657.3
A28: AU052 | B28: AU010010 | C28: 5140001010 | D28: External Training and Seminars | E28: 5517.56 | F28: AUQ | G28: 45404 | H28: CCMS | I28: AuYeungS-Default Licensee Merc | K28: USA GreenBiz Sustainability event - payable by the US team | M28: GREENBIZ GROUP INC/GREENBIZ 24/RDNTNKS38YJ | Q28: =ABS(E28) -> 5517.56
A29: AU052 | B29: AU010030 | C29: 5140001010 | D29: External Training and Seminars | E29: 5505.26 | F29: AUQ | G29: 45519 | H29: AP Accruals | I29: MEMC242553-AAUST105 | K29: ACI 12 x users | L29: MEMC242553 | M29: AUSTRALIAN COMPLIANCE INSTITUTE | Q29: =ABS(E29) -> 5505.26
A30: AU052 | B30: AU020099 | C30: 5140001010 | D30: External Training and Seminars | E30: 5241.82 | F30: AUQ | G30: 45538 | H30: AP Accruals | I30: INV-6873-ALANG01 | K30: Langley Group Strength Profile | L30: INV-6873 | M30: LANGLEY GROUP PTY LTD | Q30: =ABS(E30) -> 5241.82
A31: AU001 | B31: AU032074 | C31: 5140001010 | D31: External Training and Seminars | E31: 5231.02 | F31: AUQ | G31: 45602 | H31: AP Accruals | I31: INV-1291-ATRAN10 | K31: SuccessionSessions_QLD_Facilit | L31: INV-1291 | M31: TRANSITION PARTNERS | Q31: =ABS(E31) -> 5231.02
A32: AU052 | B32: AU010021 | C32: 5140001010 | D32: External Training and Seminars | E32: 4948.2 | F32: AUQ | G32: 45554 | H32: AP Accruals | I32: 63507-AVALI01 | K32: Furniture Hire for ALT event | L32: 63507 | M32: VALIANT COMMERCIAL FURNITURE PTY LTD | Q32: =ABS(E32) -> 4948.2
A33: AU052 | B33: AU010014 | C33: 5140001010 | D33: External Training and Seminars | E33: 4183.7 | F33: AUQ | G33: 45546 | H33: AP Accruals | I33: 22228-OMEND00 | K33: Coaching Masterclass Sessions | L33: 22228 | M33: MEND B.V. | Q33: =ABS(E33) -> 4183.7
A34: AU052 | B34: AU010014 | C34: 5140001010 | D34: External Training and Seminars | E34: 4098.39 | F34: AUQ | G34: 45497 | H34: AP Accruals | I34: 22224-OMEND00 | K34: Masterclass Sessions July | L34: 22224 | M34: MEND B.V. | Q34: =ABS(E34) -> 4098.39
A35: AU052 | B35: AU025100 | C35: 5140001010 | D35: External Training and Seminars | E35: 4036.36 | F35: AUQ | G35: 45555 | H35: CCMS | I35: knowlesp-Default Licensee Merc | J35: AusPayNet Summit 2024 | O35: AUSTRALIAN PAYMENTS NE | Q35: =ABS(E35) -> 4036.36
A36: AU052 | B36: AU071197 | C36: 5140001010 | D36: External Training and Seminars | E36: 3929.85 | F36: AUQ | G36: 45475 | H36: AP Accruals | I36: 00058-AWILL01 | K36: RaboResearch Culture Training | L36: 00058 | M36: WILLIAM ALASTAIR WHITE | Q36: =ABS(E36) -> 3929.85
A37: AU001 | B37: AU071197 | C37: 5140001010 | D37: External Training and Seminars | E37: 3843.1 | F37: AUQ | G37: 45631 | H37: AP Accruals | I37: 00094-AWILL01 | K37: Alastair White Virtual Trainin | L37: 00094 | M37: WILLIAM ALASTAIR WHITE | Q37: =ABS(E37) -> 3843.1
A38: AU001 | B38: AU032074 | C38: 5140001010 | D38: External Training and Seminars | E38: 3797.49 | F38: AUQ | G38: 45448 | H38: AP Accruals | I38: INV-1253-ATRAN10 | L38: INV-1253 | M38: TRANSITION PARTNERS | Q38: =ABS(E38) -> 3797.49
A39: AU052 | B39: AU010014 | C39: 5140001010 | D39: External Training and Seminars | E39: 3583.64 | F39: AUQ | G39: 45400 | H39: AP Accruals | I39: 22205-OMEND00 | K39: Coaching Masterclass Leadershi | L39: 22205 | M39: MEND B.V. | Q39: =ABS(E39) -> 3583.64
A40: AU001 | B40: AU070150 | C40: 5140001010 | D40: External Training and Seminars | E40: 3575 | F40: AUQ | G40: 45450 | H40: AP Accruals | I40: 00000207-AZAVE00 | L40: 00000207 | M40: ZAVESKY CONSULTING | Q40: =ABS(E40) -> 3575
...

Sheet Training Travel&lodging
A1: Account Number | C1: =Summary!A10 -> 5140001030
A2: Account Name | C2: =Summary!B10 -> Training travel and lodging ex | G2: Notes:
A3: GL Total | C3: 58301.3 | G3: Expenditure on university courses and other courses conferences attended by employees. These are not considered REAP but are in | AC3: Totals | AD3: =SUM(AD8:AD1048576) -> 0 | AE3: =SUM(AE8:AE1048576) -> 0
A4: Per TB | C4: =SUM(E:E) -> 58301.3 | G4: relation to the employees current roles so would be otherwise deductible for income tax purposes. No FBT will apply to these expenses. | T4: AU001 | V4: =SUMIF($A$10:$A$23974,"AU001",V9:V23973) -> 0
A5: Variance | C5: =C3-C4 -> 0 | T5: AU052 | V5: =SUMIF($A$10:$A$23975,"AU052",V9:V23974) -> 35.88
AD6: Income tax purposes
A7: BUSINESS_UNIT_CODE | B7: OPERATING_UNIT_CODE | C7: ACCOUNT_CODE | D7: DESCRIPTION | E7: BASE_AMOUNT | F7: BASE_CURRENCY_CODE | G7: JOURNAL_DATE | H7: DESCR | I7: LINE_DESCR | J7: PURPOSE | K7: INVOICE_DESCR | L7: INVOICE_ID | M7: VENDOR_NAME | N7: EMPLOYEE_NAME | O7: CHARGE_DESCRIPTION | Q7: ABS | R7: Search Terms | S7: Tax Description | T7: ME? Y/N | U7: OU | V7: ME $ | W7: Not ME but other type of FB Y/N | X7: Not ME but other type of FB ==> $ | Y7: Nets to Nil in GL accts | Z7: s58P M&I or Bus Exp - notFB | AA7: ME | AB7: Car FB - addn op costs | AC7: CP Exp FB | AD7: Capital expenditure | AE7: No FBT and not ded | AF7: Additional Comments
A8: AU052 | B8: AU030055 | C8: 5140001030 | D8: Training travel and lodging ex | E8: 9019.28 | F8: AUQ | G8: 45624 | H8: CCMS | I8: MckinnonR-Domestic & Overseas | K8: Accommodation for the facilitators and VICTAS staff traveling for RRB training in Melbourne (13th & | O8: Novotel On Collins OPI | Q8: =ABS(E8) -> 9019.28 | S8: business related
A9: AU001 | B9: AU032074 | C9: 5140001030 | D9: Training travel and lodging ex | E9: 5715.45 | F9: AUQ | G9: 45530 | H9: AP Accruals | I9: RAB057-AHUDS00 | K9: FSW_Longreach/Blackhall/Emeral | L9: RAB057 | M9: HUDSON FACILITATION PTY LTD | Q9: =ABS(E9) -> 5715.45
A10: AU001 | B10: AU032074 | C10: 5140001030 | D10: Training travel and lodging ex | E10: 4817.63 | F10: AUQ | G10: 45510 | H10: AP Accruals | I10: RAB055-AHUDS00 | K10: FSW_Pittsworth/Goondiwindi_Jul | L10: RAB055 | M10: HUDSON FACILITATION PTY LTD | Q10: =ABS(E10) -> 4817.63
A11: AU001 | B11: AU030055 | C11: 5140001030 | D11: Training travel and lodging ex | E11: 4121.29 | F11: AUQ | G11: 45581 | H11: AP Accruals | I11: 1592537-APARK01 | K11: Accommodation RCA participant | L11: 1592537 | M11: PARKROYAL DARLING HARBOUR | Q11: =ABS(E11) -> 4121.29
A12: AU001 | B12: AU032074 | C12: 5140001030 | D12: Training travel and lodging ex | E12: 3339.11 | F12: AUQ | G12: 45484 | H12: AP Accruals | I12: RAB054-AHUDS00 | L12: RAB054 | M12: HUDSON FACILITATION PTY LTD | Q12: =ABS(E12) -> 3339.11
A13: AU001 | B13: AU032074 | C13: 5140001030 | D13: Training travel and lodging ex | E13: 3196.01 | F13: AUQ | G13: 45586 | H13: AP Accruals | I13: RAB062-AHUDS00 | K13: FSW_Arthurton&Spalding_Facilit | L13: RAB062 | M13: HUDSON FACILITATION PTY LTD | Q13: =ABS(E13) -> 3196.01
A14: AU001 | B14: AU032074 | C14: 5140001030 | D14: Training travel and lodging ex | E14: 3186.76 | F14: AUQ | G14: 45553 | H14: AP Accruals | I14: RAB060-AHUDS00 | K14: FSW_Inverell/Tamworth_Sep_Faci | L14: RAB060 | M14: HUDSON FACILITATION PTY LTD | Q14: =ABS(E14) -> 3186.76
A15: AU001 | B15: AU032074 | C15: 5140001030 | D15: Training travel and lodging ex | E15: 2954.32 | F15: AUQ | G15: 45552 | H15: AP Accruals | I15: RAB058-AHUDS00 | K15: FSW_Ongerup_13Aug_FacilitatorT | L15: RAB058 | M15: HUDSON FACILITATION PTY LTD | Q15: =ABS(E15) -> 2954.32
A16: AU052 | B16: AU061134 | C16: 5140001030 | D16: Training travel and lodging ex | E16: 2106 | F16: AUQ | G16: 45635 | H16: AP Accruals | I16: 20250224.2-ACROW18 | K16: Treasury Offsite | L16: 20250224.2 | M16: CROWNE PLAZA TERRIGAL PACIFIC | Q16: =ABS(E16) -> 2106 | S16: Accept seminar
A17: AU052 | B17: AU061134 | C17: 5140001030 | D17: Training travel and lodging ex | E17: 2106 | F17: AUQ | G17: 45635 | H17: AP Accruals | I17: 20250224.3-ACROW18 | K17: Treasury Offsite | L17: 20250224.3 | M17: CROWNE PLAZA TERRIGAL PACIFIC | Q17: =ABS(E17) -> 2106 | S17: Accept seminar
A18: AU001 | B18: AU032074 | C18: 5140001030 | D18: Training travel and lodging ex | E18: 1865.34 | F18: AUQ | G18: 45510 | H18: AP Accruals | I18: RAB056-AHUDS00 | K18: FSW_Finley/Colleambally_Jul_Tr | L18: RAB056 | M18: HUDSON FACILITATION PTY LTD | Q18: =ABS(E18) -> 1865.34
A19: AU001 | B19: AU032074 | C19: 5140001030 | D19: Training travel and lodging ex | E19: 1844.82 | F19: AUQ | G19: 45553 | H19: AP Accruals | I19: INV-1282-ATRAN10 | K19: SuccessionPlanningInformationS | L19: INV-1282 | M19: TRANSITION PARTNERS | Q19: =ABS(E19) -> 1844.82
A20: AU001 | B20: AU032074 | C20: 5140001030 | D20: Training travel and lodging ex | E20: 1380.73 | F20: AUQ | G20: 45553 | H20: AP Accruals | I20: INV-1279-ATRAN10 | K20: SuccessionPlanningInformationS | L20: INV-1279 | M20: TRANSITION PARTNERS | Q20: =ABS(E20) -> 1380.73
A21: AU052 | B21: AU030055 | C21: 5140001030 | D21: Training travel and lodging ex | E21: 879.25 | F21: AUQ | G21: 45601 | H21: AP Accruals | I21: EEC-830-ESMIT23 | K21: Edwina Smith- Expenses for RCA | L21: EEC-830 | M21: EDWINA SMITH | Q21: =ABS(E21) -> 879.25
A22: AU052 | B22: AU076174 | C22: 5140001030 | D22: Training travel and lodging ex | E22: 868.15 | F22: AUQ | G22: 45404 | H22: CCMS | I22: MiddletonM-Default Licensee Me | J22: PIX Conference | O22: KAM EVENTS | Q22: =ABS(E22) -> 868.15
A23: AU052 | B23: AU030217 | C23: 5140001030 | D23: Training travel and lodging ex | E23: 755.22 | F23: AUQ | G23: 45580 | H23: AP Accruals | I23: EEC-768-EFALC02 | K23: Hotel Claim | L23: EEC-768 | M23: LAUREN FALCONER | Q23: =ABS(E23) -> 755.22
A24: AU052 | B24: AU030317 | C24: 5140001030 | D24: Training travel and lodging ex | E24: 681.82 | F24: AUQ | G24: 45594 | H24: CCMS | I24: BennettA-Domestic & Overseas l | J24: Accommodation in Sydney for RCA | O24: Park Royal Darl Harb OPI | Q24: =ABS(E24) -> 681.82 | S24: Accept business travel food
A25: AU052 | B25: AU032074 | C25: 5140001030 | D25: Training travel and lodging ex | E25: 542.27 | F25: AUQ | G25: 45386 | H25: CCMS | I25: PozziB-Offshore Meals & Lodgin | K25: Financial Skills Workshop Catering Charters Towers 22March - Brad Pozzi | O25: SANTONS GOURMET HOAGIES | Q25: =ABS(E25) -> 542.27
A26: AU001 | B26: AU030325 | C26: 5140001030 | D26: Training travel and lodging ex | E26: 517.44 | F26: AUQ | G26: 45631 | H26: AP Accruals | I26: 31-AAUST23 | K26: Accommodation for Cameron De K | L26: 31 | M26: AUSTRALIAN DAIRY CONFERENCE | Q26: =ABS(E26) -> 517.44
A27: AU052 | B27: AU025080 | C27: 5140001030 | D27: Training travel and lodging ex | E27: 466.27 | F27: AUQ | G27: 45558 | H27: CCMS | I27: NazarenoJ-Airfares | J27: NGON - NZ4 - Flight | O27: EGEN*AUSI142497951/AUBI2024260417261/AUBI2024260417261650 | Q27: =ABS(E27) -> 466.27
A28: AU052 | B28: AU030410 | C28: 5140001030 | D28: Training travel and lodging ex | E28: 460.23 | F28: AUQ | G28: 45607 | H28: CCMS | I28: FlynnA-Domestic & Overseas lod | K28: Accomodation as part of trip to Sydney for Rural Credit Training. | O28: Park Royal Darl Harb OPI | Q28: =ABS(E28) -> 460.23
A29: AU052 | B29: AU032074 | C29: 5140001030 | D29: Training travel and lodging ex | E29: 431.82 | F29: AUQ | G29: 45386 | H29: CCMS | I29: WeatherlyC-Offshore Meals & Lo | K29: Lunch FSW | O29: SQ *PETALS & PINECONES | Q29: =ABS(E29) -> 431.82 | S29: Accept seminar food
A30: AU052 | B30: AU030313 | C30: 5140001030 | D30: Training travel and lodging ex | E30: 398.45 | F30: AUQ | G30: 45639 | H30: CCMS | I30: RistromJ-Airfares | K30: Airfares for travel to RCA training Sydney | O30: VIRGIN AUSTR/79534850626969/79534850626969 | Q30: =ABS(E30) -> 398.45
A31: AU052 | B31: AU030317 | C31: 5140001030 | D31: Training travel and lodging ex | E31: 369.1 | F31: AUQ | G31: 45594 | H31: CCMS | I31: BennettA-Airfares | K31: Flights to sydney for RCA | O31: VIRGIN AUSTR/79558153577409/79558153577409 | Q31: =ABS(E31) -> 369.1
A32: AU052 | B32: AU032074 | C32: 5140001030 | D32: Training travel and lodging ex | E32: 330 | F32: AUQ | G32: 45386 | H32: CCMS | I32: WeatherlyC-Default Licensee Me | K32: venue hire | O32: TABLELANDS R C | Q32: =ABS(E32) -> 330
A33: AU052 | B33: AU030510 | C33: 5140001030 | D33: Training travel and lodging ex | E33: 314.2 | F33: AUQ | G33: 45464 | H33: CCMS | I33: PriceC-Default Licensee Mercha | K33: Horsham Culture Workshop - SYD MEL Return May 24 - N Cross | O33: QANTAS AIR_ABN16009661901/NXGZNWNVGKJNQR32/NXGZNWNVGKJNQR32 | Q33: =ABS(E33) -> 314.2
A34: AU052 | B34: AU030430 | C34: 5140001030 | D34: Training travel and lodging ex | E34: 311.35 | F34: AUQ | G34: 45601 | H34: AP Accruals | I34: EEC-835-EFINL00 | K34: Expenses for RCA Training Syd | L34: EEC-835 | M34: VIVIAN FINLAY | Q34: =ABS(E34) -> 311.35
A35: AU052 | B35: AU020080 | C35: 5140001030 | D35: Training travel and lodging ex | E35: 303 | F35: AUQ | G35: 45510 | H35: AP Accruals | I35: EEC-406-ENGUY01 | K35: Utrecht trip 22-28June 2024 | L35: EEC-406 | M35: HAI NGUYEN | Q35: =ABS(E35) -> 303
A36: AU052 | B36: AU032074 | C36: 5140001030 | D36: Training travel and lodging ex | E36: 290.91 | F36: AUQ | G36: 45449 | H36: CCMS | I36: WebbO-Default Licensee Merchan | K36: FinancialSkillsWorkshops_Goondiwindi_17Jul_VenueHire | O36: GATEWAY TO TRAINING | Q36: =ABS(E36) -> 290.91
A37: AU052 | B37: AU030415 | C37: 5140001030 | D37: Training travel and lodging ex | E37: 283.35 | F37: AUQ | G37: 45601 | H37: AP Accruals | I37: EEC-868-ELYDD00 | K37: Meals & Taxis during RCA train | L37: EEC-868 | M37: SANDY LYDDY | Q37: =ABS(E37) -> 283.35
A38: AU052 | B38: AU030510 | C38: 5140001030 | D38: Training travel and lodging ex | E38: 266.99 | F38: AUQ | G38: 45464 | H38: CCMS | I38: PriceC-Default Licensee Mercha | K38: Airfare SYD ADL RRM3 Training | O38: QANTAS AIR_ABN16009661901/QWPFZ9CRMLG74FH2/QWPFZ9CRMLG74FH2 | Q38: =ABS(E38) -> 266.99
A39: AU052 | B39: AU030316 | C39: 5140001030 | D39: Training travel and lodging ex | E39: 215.94 | F39: AUQ | G39: 45628 | H39: CCMS | I39: WilsonE3-Domestic & Overseas l | K39: 1 x night accomodation at Holiday Inn as part of Rural Credit Academy training in Sydney | O39: Holiday Inn Melb Airport | Q39: =ABS(E39) -> 215.94
A40: AU052 | B40: AU030316 | C40: 5140001030 | D40: Training travel and lodging ex | E40: 208.15 | F40: AUQ | G40: 45628 | H40: CCMS | I40: WilsonE3-Default Licensee Merc | K40: Melbourne to Sydney flight | O40: QANTAS AIR_ABN16009661901/VMSVLL9KC9G5XJF3/VMSVLL9KC9G5XJF3 | Q40: =ABS(E40) -> 208.15
...

Sheet Publicity&Advertising
A1: Account Number | C1: =Summary!A11 -> 5160001000
A2: Account Name | C2: =Summary!B11 -> Publicity/advertising | G2: Notes:
A3: GL Total | C3: 5130256.9 | G3: Rabobank truck expenses have been treated as deductible on the basis that they are a marketing expense under s8-1 | T3: AU001 | U3: =SUMIF($A$10:$A$408,"AU001",U9:U408) -> 1413.94 | AB3: AU001 | AC3: =SUMIF($A$8:$A$408,"AU001",AC8:AC408) -> 0 | AD3: =SUMIF($A$8:$A$408,"AU001",AD8:AD408) -> 0
A4: Per TB | C4: =SUM(E:E) -> 5130256.9 | G4: Mostly, No entertainment expenses included below - all relates to Rabotruck, marketing expences and items directly related to businss activities of Rabo | T4: AU052 | U4: =SUMIF($A$10:$A$408,"AU052",U9:U408) -> 0 | AB4: AU052 | AC4: =SUMIF($A$8:$A$408,"AU052",AC8:AC408) -> 426.45 | AD4: =SUMIF($A$8:$A$408,"AU052",AD8:AD408) -> 0
A5: Variance | C5: =C3-C4 -> 0
AC6: Income tax purposes
A7: BUSINESS_UNIT_CODE | B7: OPERATING_UNIT_CODE | C7: ACCOUNT_CODE | D7: DESCRIPTION | E7: BASE_AMOUNT | F7: BASE_CURRENCY_CODE | G7: JOURNAL_DATE | H7: DESCR | I7: LINE_DESCR | J7: PURPOSE | K7: INVOICE_DESCR | L7: INVOICE_ID | M7: VENDOR_NAME | N7: EMPLOYEE_NAME | O7: CHARGE_DESCRIPTION | Q7: ABS | R7: Search Terms | S7: Tax Description | T7: ME? Y/N | U7: ME $ | V7: Not ME but other type of FB Y/N | W7: Not ME but other type of FB ==> $ | X7: Nets to Nil in GL accts | Y7: s58P M&I or Bus Exp - notFB | Z7: ME | AA7: Car FB - addn op costs | AB7: CP Exp FB | AC7: Capital expenditure | AD7: No FBT and not ded | AE7: Additional Comments
A8: AU001 | B8: AU032051 | C8: 5160001000 | D8: Publicity/advertising | E8: 295420.77 | F8: AUQ | G8: 45436 | H8: AP Accruals | I8: INV-12836-ABRYA02 | L8: INV-12836 | M8: BRYANT AND BROTHERS PTY LTD TA SPARRO | Q8: =ABS(E8) -> 295420.77
A9: AU001 | B9: AU032051 | C9: 5160001000 | D9: Publicity/advertising | E9: 242000 | F9: AUQ | G9: 45642 | I9: Rabobank ROS Paid Media-Dec24 | K9: RaboTruck Operation (MNGT fee) | Q9: =ABS(E9) -> 242000
A10: AU001 | B10: AU032051 | C10: 5160001000 | D10: Publicity/advertising | E10: 181315.6 | F10: AUQ | G10: 45397 | H10: AP Accruals | I10: INV-12575-ABRYA02 | K10: Sparro Agency - 2024 Febrauary | L10: INV-12575 | M10: BRYANT AND BROTHERS PTY LTD TA SPARRO | Q10: =ABS(E10) -> 181315.6
A11: AU001 | B11: AU032051 | C11: 5160001000 | D11: Publicity/advertising | E11: 175066.13 | F11: AUQ | G11: 45436 | H11: AP Accruals | I11: INV-13055-ABRYA02 | K11: ROS Search Marketing - April 2 | L11: INV-13055 | M11: BRYANT AND BROTHERS PTY LTD TA SPARRO | Q11: =ABS(E11) -> 175066.13
A12: AU001 | B12: AU032051 | C12: 5160001000 | D12: Publicity/advertising | E12: 155044.16 | F12: AUQ | G12: 45492 | H12: AP Accruals | I12: INV-13346-ABRYA02 | K12: ROS paid media - Search Market | L12: INV-13346 | M12: BRYANT AND BROTHERS PTY LTD TA SPARRO | Q12: =ABS(E12) -> 155044.16
A13: AU001 | B13: AU032051 | C13: 5160001000 | D13: Publicity/advertising | E13: 150728.37 | F13: AUQ | G13: 45512 | H13: AP Accruals | I13: INV-13504-ABRYA02 | K13: ROS search marketing campaigns | L13: INV-13504 | M13: BRYANT AND BROTHERS PTY LTD TA SPARRO | Q13: =ABS(E13) -> 150728.37
A14: AU001 | B14: AU032051 | C14: 5160001000 | D14: Publicity/advertising | E14: 150306.54 | F14: AUQ | G14: 45601 | H14: AP Accruals | I14: INV-13978-ABRYA02 | K14: ROS paid Media - Affiliate cam | L14: INV-13978 | M14: BRYANT AND BROTHERS PTY LTD TA SPARRO | Q14: =ABS(E14) -> 150306.54
A15: AU001 | B15: AU032051 | C15: 5160001000 | D15: Publicity/advertising | E15: 146419.87 | F15: AUQ | G15: 45614 | H15: AP Accruals | I15: INV-14200-ABRYA02 | K15: ROS paid performance - Septemb | L15: INV-14200 | M15: BRYANT AND BROTHERS PTY LTD TA SPARRO | Q15: =ABS(E15) -> 146419.87
A16: AU001 | B16: AU032046 | C16: 5160001000 | D16: Publicity/advertising | E16: 139758.78 | F16: AUQ | G16: 45492 | H16: AP Accruals | I16: INV-13384-ABRYA02 | K16: Rabobank Country Banking - Bee | L16: INV-13384 | M16: BRYANT AND BROTHERS PTY LTD TA SPARRO | Q16: =ABS(E16) -> 139758.78
A17: AU001 | B17: AU032051 | C17: 5160001000 | D17: Publicity/advertising | E17: 134101.14 | F17: AUQ | G17: 45601 | H17: AP Accruals | I17: INV-13985-ABRYA02 | K17: Rabobank ROS - Search Marketin | L17: INV-13985 | M17: BRYANT AND BROTHERS PTY LTD TA SPARRO | Q17: =ABS(E17) -> 134101.14
A18: AU001 | B18: AU032051 | C18: 5160001000 | D18: Publicity/advertising | E18: 132017.26 | F18: AUQ | G18: 45554 | H18: AP Accruals | I18: INV-13757-ABRYA02 | K18: Rabobank search marketing camp | L18: INV-13757 | M18: BRYANT AND BROTHERS PTY LTD TA SPARRO | Q18: =ABS(E18) -> 132017.26
A19: AU001 | B19: AU032051 | C19: 5160001000 | D19: Publicity/advertising | E19: 127528.63 | F19: AUQ | G19: 45492 | H19: AP Accruals | I19: INV-13238-ABRYA02 | K19: ROS Paid Media May 2024 - Affi | L19: INV-13238 | M19: BRYANT AND BROTHERS PTY LTD TA SPARRO | Q19: =ABS(E19) -> 127528.63
A20: AU001 | B20: AU032051 | C20: 5160001000 | D20: Publicity/advertising | E20: 125980.49 | F20: AUQ | G20: 45512 | H20: AP Accruals | I20: INV-13512-ABRYA02 | K20: ROS affiliate marketing campai | L20: INV-13512 | M20: BRYANT AND BROTHERS PTY LTD TA SPARRO | Q20: =ABS(E20) -> 125980.49
A21: AU001 | B21: AU032051 | C21: 5160001000 | D21: Publicity/advertising | E21: 123000.77 | F21: AUQ | G21: 45492 | H21: AP Accruals | I21: INV-12922-ABRYA02 | K21: ROS paid media April 2024 - af | L21: INV-12922 | M21: BRYANT AND BROTHERS PTY LTD TA SPARRO | Q21: =ABS(E21) -> 123000.77
A22: AU001 | B22: AU032046 | C22: 5160001000 | D22: Publicity/advertising | E22: 107045.4 | F22: AUQ | G22: 45642 | I22: Rabo CB Paid Media-Brand-Oct24 | K22: RaboTruck Operation (MNGT fee) | Q22: =ABS(E22) -> 107045.4
A23: AU001 | B23: AU032051 | C23: 5160001000 | D23: Publicity/advertising | E23: 106042.48 | F23: AUQ | G23: 45636 | H23: AP Accruals | I23: INV-14392-ABRYA02 | K23: ROS paid media - Search Market | L23: INV-14392 | M23: BRYANT AND BROTHERS PTY LTD TA SPARRO | Q23: =ABS(E23) -> 106042.48
A24: AU001 | B24: AU032051 | C24: 5160001000 | D24: Publicity/advertising | E24: 102444.18 | F24: AUQ | G24: 45554 | H24: AP Accruals | I24: INV-13878-ABRYA02 | K24: ROS paid performance - July 20 | L24: INV-13878 | M24: BRYANT AND BROTHERS PTY LTD TA SPARRO | Q24: =ABS(E24) -> 102444.18
A25: AU001 | B25: AU032051 | C25: 5160001000 | D25: Publicity/advertising | E25: 100639.5 | F25: AUQ | G25: 45614 | H25: AP Accruals | I25: INV-14191-ABRYA02 | K25: ROS affiliated marketing campa | L25: INV-14191 | M25: BRYANT AND BROTHERS PTY LTD TA SPARRO | Q25: =ABS(E25) -> 100639.5
A26: AU001 | B26: AU032051 | C26: 5160001000 | D26: Publicity/advertising | E26: 97293.9 | F26: AUQ | G26: 45636 | H26: AP Accruals | I26: INV-14674-ABRYA02 | K26: ROS paid Media - Search campai | L26: INV-14674 | M26: BRYANT AND BROTHERS PTY LTD TA SPARRO | Q26: =ABS(E26) -> 97293.9
A27: AU001 | B27: AU032051 | C27: 5160001000 | D27: Publicity/advertising | E27: -75153.27 | F27: AUQ | G27: 45608 | H27: AP Accruals | I27: INV-13978-ABRYA02 | K27: ROS paid Media - Affiliate cam | L27: INV-13978 | M27: BRYANT AND BROTHERS PTY LTD TA SPARRO | Q27: =ABS(E27) -> 75153.27
A28: AU001 | B28: AU036742 | C28: 5160001000 | D28: Publicity/advertising | E28: 65000 | F28: AUQ | G28: 45642 | I28: Brand Health Survey - question | K28: RaboTruck Operation (MNGT fee) | Q28: =ABS(E28) -> 65000
A29: AU001 | B29: AU032051 | C29: 5160001000 | D29: Publicity/advertising | E29: 62569.52 | F29: AUQ | G29: 45431 | H29: AP Accruals | I29: INV-12817-ABRYA02 | K29: ROS Paid Media - Affiliate Fee | L29: INV-12817 | M29: BRYANT AND BROTHERS PTY LTD TA SPARRO | Q29: =ABS(E29) -> 62569.52
A30: AU001 | B30: AU032046 | C30: 5160001000 | D30: Publicity/advertising | E30: 61340.4 | F30: AUQ | G30: 45642 | I30: The Land advertsing camp(NSW) | K30: RaboTruck Operation (MNGT fee) | Q30: =ABS(E30) -> 61340.4
A31: AU001 | B31: AU032051 | C31: 5160001000 | D31: Publicity/advertising | E31: 60787.04 | F31: AUQ | G31: 45636 | H31: AP Accruals | I31: INV-14399-ABRYA02 | K31: ROS Paid Media - affiliates fe | L31: INV-14399 | M31: BRYANT AND BROTHERS PTY LTD TA SPARRO | Q31: =ABS(E31) -> 60787.04
A32: AU001 | B32: AU032051 | C32: 5160001000 | D32: Publicity/advertising | E32: 52840.94 | F32: AUQ | G32: 45636 | H32: AP Accruals | I32: INV-14683-ABRYA02 | K32: Paid Media - ROS Affiliate Fee | L32: INV-14683 | M32: BRYANT AND BROTHERS PTY LTD TA SPARRO | Q32: =ABS(E32) -> 52840.94
A33: AU001 | B33: AU032051 | C33: 5160001000 | D33: Publicity/advertising | E33: 51092.83 | F33: AUQ | G33: 45614 | H33: AP Accruals | I33: INV-14324-ABRYA02 | K33: Rabobank CB brand awareness ca | L33: INV-14324 | M33: BRYANT AND BROTHERS PTY LTD TA SPARRO | Q33: =ABS(E33) -> 51092.83
A34: AU001 | B34: AU032051 | C34: 5160001000 | D34: Publicity/advertising | E34: 49496.85 | F34: AUQ | G34: 45629 | H34: AP Accruals | I34: INV-14612-ABRYA02 | K34: ROS creative refresh | L34: INV-14612 | M34: BRYANT AND BROTHERS PTY LTD TA SPARRO | Q34: =ABS(E34) -> 49496.85
A35: AU001 | B35: AU032046 | C35: 5160001000 | D35: Publicity/advertising | E35: 44679.34 | F35: AUQ | G35: 45434 | H35: AP Accruals | I35: 00013081-AQUAL08 | K35: Beef 2024 marquee & furniture | L35: 00013081 | M35: QUALITY EVENT HIRE PTY LTD | Q35: =ABS(E35) -> 44679.34
A36: AU001 | B36: AU032051 | C36: 5160001000 | D36: Publicity/advertising | E36: 42072.32 | F36: AUQ | G36: 45425 | H36: AP Accruals | I36: INVCAN-900006966-ACANS00 | K36: 2024 Canstar awards licence fe | L36: INVCAN-900006966 | M36: CANSTAR PTY LIMITED | Q36: =ABS(E36) -> 42072.32
A37: AU001 | B37: AU032046 | C37: 5160001000 | D37: Publicity/advertising | E37: 34777.19 | F37: AUQ | G37: 45642 | I37: RaboTruck Operation (MNGT fee) | K37: RaboTruck Operation (MNGT fee) | Q37: =ABS(E37) -> 34777.19
A38: AU001 | B38: AU032051 | C38: 5160001000 | D38: Publicity/advertising | E38: 34644.6 | F38: AUQ | G38: 45637 | H38: AP Accruals | I38: INV-14838-ABRYA02 | K38: Paid Media Retainer fee - Nove | L38: INV-14838 | M38: BRYANT AND BROTHERS PTY LTD TA SPARRO | Q38: =ABS(E38) -> 34644.6
A39: AU001 | B39: AU032054 | C39: 5160001000 | D39: Publicity/advertising | E39: 34632.22 | F39: AUQ | G39: 45597 | H39: AP Accruals | I39: INV-0054-ANUME00 | K39: Nature 101 case study videos | L39: INV-0054 | M39: NUMERAL CREATIVE PTY LTD | Q39: =ABS(E39) -> 34632.22
A40: AU001 | B40: AU036740 | C40: 5160001000 | D40: Publicity/advertising | E40: 33408.17 | F40: AUQ | G40: 45420 | H40: AP Accruals | I40: 24330-AD3PR00 | K40: ROS Digipass trays and labels | L40: 24330 | M40: D3 PRODUCT DESIGN PTY LTD | Q40: =ABS(E40) -> 33408.17
...

Sheet Opening Jubilees
A1: Account Number | C1: =Summary!A12 -> 5160006000
A2: Account Name | C2: =Summary!B12 -> Opening jubilees own buildin | G2: Notes:
A3: GL Total | C3: =SUMIFS(#REF!,#REF!,C1) -> #REF! | G3: No entertainment expenses
A4: Per TB | C4: =SUM(D:D) -> 0 | R4: AU001 | S4: =SUMIF($A$10:$A$23974,"AU001",S9:S23973) -> 0
A5: Variance | C5: =C3-C4 -> #REF! | R5: AU052 | S5: =SUMIF($A$10:$A$23975,"AU052",S9:S23974) -> 0
AA6: Income tax purposes
A7: BUSINESS_UNIT_CODE | B7: ACCOUNT_CODE | C7: DESCRIPTION | D7: BASE_AMOUNT | E7: BASE_CURRENCY_CODE | F7: JOURNAL_DATE | G7: DESCR | H7: LINE_DESCR | I7: PURPOSE | J7: INVOICE_DESCR | K7: INVOICE_ID | L7: VENDOR_NAME | M7: EMPLOYEE_NAME | O7: ABS | P7: Search Terms | Q7: Tax Description | R7: ME? Y/N | S7: ME $ | T7: Not ME but other type of FB Y/N | U7: Not ME but other type of FB ==> $ | V7: Nets to Nil in GL accts | W7: s58P M&I or Bus Exp - notFB | X7: ME | Y7: Car FB - addn op costs | Z7: CP Exp FB | AA7: Capital expenditure | AB7: No FBT and not ded | AC7: Additional Comments

Sheet Sponsoring
A1: Account Number | C1: =Summary!A13 -> 5160007000
A2: Account Name | C2: =Summary!B13 -> Sponsoring | G2: Notes: | T2: AU001 | U2: =SUMIF($A$10:$A$23974,"AU001",U9:U23973) -> 0 | AB2: AU001 | AC2: =SUMIF($A$8:$A$408,"AU001",AC8:AC408) -> 0 | AD2: =SUMIF($A$8:$A$408,"AU001",AD8:AD408) -> 0
A3: GL Total | C3: 975192.62 | G3: No entertainment expenses included and all tax deductible | T3: AU052 | U3: =SUMIF($A$10:$A$23975,"AU052",U9:U23974) -> 0 | AB3: AU052 | AC3: =SUMIF($A$8:$A$408,"AU052",AC8:AC408) -> 0 | AD3: =SUMIF($A$8:$A$408,"AU052",AD8:AD408) -> 407.73
A4: Per TB | C4: =SUM(E:E) -> 975192.62 | G4: Charity days/community days have not been treated as recreational activity (arguably does not meet ITAA definition)
A5: Variance | C5: =C3-C4 -> 0
AC6: Income tax purposes
A7: BUSINESS_UNIT_CODE | B7: OPERATING_UNIT_CODE | C7: ACCOUNT_CODE | D7: DESCRIPTION | E7: BASE_AMOUNT | F7: BASE_CURRENCY_CODE | G7: JOURNAL_DATE | H7: DESCR | I7: LINE_DESCR | J7: PURPOSE | K7: INVOICE_DESCR | L7: INVOICE_ID | M7: VENDOR_NAME | N7: EMPLOYEE_NAME | O7: CHARGE_DESCRIPTION | Q7: ABS | R7: Search Terms | S7: Tax Description | T7: ME? Y/N | U7: ME $ | V7: Not ME but other type of FB Y/N | W7: Not ME but other type of FB ==> $ | X7: Nets to Nil in GL accts | Y7: s58P M&I or Bus Exp - notFB | Z7: ME | AA7: Car FB - addn op costs | AB7: CP Exp FB | AC7: Capital expenditure | AD7: No FBT and not ded | AE7: Additional Comments
A8: AU001 | B8: AU032074 | C8: 5160007000 | D8: Sponsoring | E8: 192250.62 | F8: AUQ | G8: 45384 | H8: AP Accruals | I8: INV-3798-ABOYS00 | K8: Boys to the Bush Sponsorship i | L8: INV-3798 | M8: BOYS TO THE BUSH LIMITED | Q8: =ABS(E8) -> 192250.62
A9: AU001 | B9: AU032074 | C9: 5160007000 | D9: Sponsoring | E9: 720.25 | F9: AUQ | G9: 45385 | H9: AP Accruals | I9: INV-2280-AGEOR00 | K9: NZ_GeorgetheFarmerBooks | L9: INV-2280 | M9: GEORGE THE FARMER PTY LTD | Q9: =ABS(E9) -> 720.25
A10: AU052 | B10: AU030212 | C10: 5160007000 | D10: Sponsoring | E10: 111.82 | F10: AUQ | G10: 45385 | H10: CCMS | I10: McKayJ-Default Licensee Mercha | J10: Tickets - MCGA Golf Day x 3 people | M10: SQ *MACQUARIE COTTON GROW | Q10: =ABS(E10) -> 111.82 | S10: recreational entertainment | AD10: =E10 -> 111.82
A11: AU052 | B11: AU010029 | C11: 5160007000 | D11: Sponsoring | E11: 500 | F11: AUQ | G11: 45390 | H11: AP Accruals | I11: 0005-AWOME06 | K11: Student society sponsorship (W | L11: 0005 | M11: WOMEN IN TECHNOLOGY WIT | Q11: =ABS(E11) -> 500
A12: AU052 | B12: AU010029 | C12: 5160007000 | D12: Sponsoring | E12: 1494.45 | F12: AUQ | G12: 45390 | H12: AP Accruals | I12: 104902-AUTSW00 | K12: Women in Business Student Soci | L12: 104902 | M12: UTS WOMEN IN BUSINESS | Q12: =ABS(E12) -> 1494.45
A13: AU052 | B13: AU010029 | C13: 5160007000 | D13: Sponsoring | E13: 464.65 | F13: AUQ | G13: 45391 | H13: CCMS | I13: SunT-Default Licensee Merchant | J13: USYD Ag Soc networking event payment | M13: SQ *SU AGRICULTURAL SOCIE | Q13: =ABS(E13) -> 464.65
A14: AU001 | B14: AU036743 | C14: 5160007000 | D14: Sponsoring | E14: 2200 | F14: AUQ | G14: 45392 | H14: AP Accruals | I14: INV-1460-ASMSF00 | K14: Joint event in Albury - Raboba | L14: INV-1460 | M14: SMSF ASSOCIATION LTD | Q14: =ABS(E14) -> 2200
A15: AU052 | B15: AU030710 | C15: 5160007000 | D15: Sponsoring | E15: 681.82 | F15: AUQ | G15: 45394 | H15: CCMS | I15: GunnHF-Office Supplies | J15: client sponsorship badcock and Melton vale x 2 years | M15: COLES 7659 | Q15: =ABS(E15) -> 681.82
A16: AU052 | B16: AU030612 | C16: 5160007000 | D16: Sponsoring | E16: 102.73 | F16: AUQ | G16: 45394 | H16: CCMS | I16: MELVILLER-Entertainment Expens | J16: Morawa P & C Sponsorship | M16: LIQUORLAND 3083 | Q16: =ABS(E16) -> 102.73 | S16: accept provided to client
A17: AU052 | B17: AU030512 | C17: 5160007000 | D17: Sponsoring | E17: 45.45 | F17: AUQ | G17: 45398 | H17: CCMS | I17: ArnoldS-Default Licensee Merch | J17: Voucher for sponsorship of Kimba Cup | M17: G PEDEMONTE MANUFACTURING | Q17: =ABS(E17) -> 45.45
A18: AU052 | B18: AU075166 | C18: 5160007000 | D18: Sponsoring | E18: 1590.91 | F18: AUQ | G18: 45432 | H18: CCMS | I18: GrootJ5-Default Licensee Merch | J18: sponsorship kingsday event | M18: ROYAL NETHERLANDS EM | Q18: =ABS(E18) -> 1590.91
A19: AU052 | B19: AU010029 | C19: 5160007000 | D19: Sponsoring | E19: 450 | F19: AUQ | G19: 45440 | H19: AP Accruals | I19: FFINV-24020-AUNEF00 | L19: FFINV-24020 | M19: UNE FARMING FUTURES | Q19: =ABS(E19) -> 450
A20: AU001 | B20: AU032066 | C20: 5160007000 | D20: Sponsoring | E20: 4617.36 | F20: AUQ | G20: 45447 | H20: AP Accruals | I20: ATASA00376-AAGRI23 | L20: ATASA00376 | M20: AGRICULTURAL TEACHERS ASSOCIATION OF SA | Q20: =ABS(E20) -> 4617.36
A21: AU052 | B21: AU070150 | C21: 5160007000 | D21: Sponsoring | E21: 7000 | F21: AUQ | G21: 45449 | H21: AP Accruals | I21: INV-1934-AGIAN01 | K21: Giant Steps annual ball | L21: INV-1934 | M21: GIANT STEPS AUSTRALIA LIMITED | Q21: =ABS(E21) -> 7000
A22: AU052 | B22: AU073133 | C22: 5160007000 | D22: Sponsoring | E22: 8382.86 | F22: AUQ | G22: 45457 | H22: AP Accruals | I22: 0127-OSUGA00 | K22: Ticket to Dubai Sugar Conferen | L22: 0127 | M22: SUGAR CONFERENCE ORGANIZERS L.L.C. | Q22: =ABS(E22) -> 8382.86
A23: AU001 | B23: AU032054 | C23: 5160007000 | D23: Sponsoring | E23: 6515.79 | F23: AUQ | G23: 45461 | H23: AP Accruals | I23: INV-3475-ACARB02 | L23: INV-3475 | M23: CARBON MARKET INSTITUTE LIMITED | Q23: =ABS(E23) -> 6515.79
A24: AU052 | B24: AU073158 | C24: 5160007000 | D24: Sponsoring | E24: 1650 | F24: AUQ | G24: 45463 | H24: AP Accruals | I24: 1800000325-ATULL08 | L24: 1800000325 | M24: TULLY SUGAR LIMITED | Q24: =ABS(E24) -> 1650
A25: AU001 | B25: AU032062 | C25: 5160007000 | D25: Sponsoring | E25: 2775.1 | F25: AUQ | G25: 45481 | H25: AP Accruals | I25: 5861-ACOTT07 | L25: 5861 | M25: COTTON AUSTRALIA LTD | Q25: =ABS(E25) -> 2775.1
A26: AU001 | B26: AU032064 | C26: 5160007000 | D26: Sponsoring | E26: 7631.54 | F26: AUQ | G26: 45488 | H26: AP Accruals | I26: 310029263-ANSWH00 | L26: 310029263 | M26: NSW HEALTH MURRUMBIDGEE LOCAL HEALTH | Q26: =ABS(E26) -> 7631.54
A27: AU001 | B27: AU070150 | C27: 5160007000 | D27: Sponsoring | E27: 2000 | F27: AUQ | G27: 45490 | H27: AP Accruals | I27: INV-1121-AONET01 | K27: One Tree Ag RU OK Day Sponosrs | L27: INV-1121 | M27: ONE TREE AGRICULTURAL PTY LTD | Q27: =ABS(E27) -> 2000
A28: AU052 | B28: AU073133 | C28: 5160007000 | D28: Sponsoring | E28: -8382.86 | F28: AUQ | G28: 45504 | H28: Jul 24 YTD Clear to AU073158 | I28: Jul 24 YTD Clear to AU073158 | Q28: =ABS(E28) -> 8382.86
A29: AU052 | B29: AU073158 | C29: 5160007000 | D29: Sponsoring | E29: 8382.86 | F29: AUQ | G29: 45504 | H29: Jul 24 YTD Clear to AU073158 | I29: Jul 24 YTD Clear to AU073158 | Q29: =ABS(E29) -> 8382.86
A30: AU001 | B30: AU032061 | C30: 5160007000 | D30: Sponsoring | E30: 2969.85 | F30: AUQ | G30: 45511 | H30: AP Accruals | I30: 24023-AABLF00 | K30: ABL_NQNT_July_Sponsorship | L30: 24023 | M30: ABL FOUNDATION LIMITED | Q30: =ABS(E30) -> 2969.85
A31: AU001 | B31: AU032062 | C31: 5160007000 | D31: Sponsoring | E31: 4959.02 | F31: AUQ | G31: 45511 | H31: AP Accruals | I31: 24023-AABLF00 | K31: ABL_SQ_July_Sponsorship | L31: 24023 | M31: ABL FOUNDATION LIMITED | Q31: =ABS(E31) -> 4959.02
A32: AU052 | B32: AU030512 | C32: 5160007000 | D32: Sponsoring | E32: 454.55 | F32: AUQ | G32: 45511 | H32: CCMS | I32: ArnoldS-Other Personnel Expens | J32: Support for Lock Health Night | M32: WISH GIFT CARD 6673 | Q32: =ABS(E32) -> 454.55
A33: AU001 | B33: AU032074 | C33: 5160007000 | D33: Sponsoring | E33: 54511 | F33: AUQ | G33: 45516 | H33: AP Accruals | I33: 00000713-AHEAR01 | K33: HeartofAustralia_National_Spon | L33: 00000713 | M33: HEART OF AUSTRALIA | Q33: =ABS(E33) -> 54511
A34: AU052 | B34: AU073158 | C34: 5160007000 | D34: Sponsoring | E34: 7958.78 | F34: AUQ | G34: 45516 | H34: CCMS | I34: Haynest-Entertainment Expense | J34: NZX Global Dairy Seminar 2024 Badge Sponsor - per Graydon | M34: NZX Limited | Q34: =ABS(E34) -> 7958.78
A35: AU052 | B35: AU030313 | C35: 5160007000 | D35: Sponsoring | E35: 1500 | F35: AUQ | G35: 45519 | H35: AP Accruals | I35: RABO-11/06/24-AWELL02 | K35: Sponsorship | L35: RABO-11/06/24 | M35: WELLINGTON BBBBQ INC | Q35: =ABS(E35) -> 1500
A36: AU052 | B36: AU032046 | C36: 5160007000 | D36: Sponsoring | E36: 126233.2 | F36: AUQ | G36: 45530 | H36: AP Accruals | I36: SINV110-002283-ANATI01 | K36: Partnership Fee Aug 2022- Jul | L36: SINV110-002283 | M36: NATIONAL FARMERS FEDERATION | Q36: =ABS(E36) -> 126233.2
A37: AU052 | B37: AU032046 | C37: 5160007000 | D37: Sponsoring | E37: 131721.6 | F37: AUQ | G37: 45530 | H37: AP Accruals | I37: SINV110-002284-ANATI01 | K37: Partnership Fee Aug 2023- Jul | L37: SINV110-002284 | M37: NATIONAL FARMERS FEDERATION | Q37: =ABS(E37) -> 131721.6
A38: AU001 | B38: AU070150 | C38: 5160007000 | D38: Sponsoring | E38: 10000 | F38: AUQ | G38: 45540 | H38: AP Accruals | I38: 06202414-AMANI01 | K38: Gold Sponsorship of Harwood Mi | L38: 06202414 | M38: MANILDRA HARWOOD SUGARS | Q38: =ABS(E38) -> 10000
A39: AU052 | B39: AU073133 | C39: 5160007000 | D39: Sponsoring | E39: 0 | F39: AUQ | G39: 45544 | H39: Clear OU | I39: Clear OU | Q39: =ABS(E39) -> 0
A40: AU001 | B40: AU020099 | C40: 5160007000 | D40: Sponsoring | E40: 1493.82 | F40: AUQ | G40: 45545 | H40: AP Accruals | I40: PSI0015711-ASTVI01 | K40: Staff Community day at Matthew | L40: PSI0015711 | M40: ST VINCENT DE PAUL SOCIETY | Q40: =ABS(E40) -> 1493.82
...

Sheet Promotional gifts
A1: Account Number | C1: =Summary!A14 -> 5160008000
A2: Account Name | C2: =Summary!B14 -> Promotional gifts | G2: Notes:
A3: GL Total | C3: 61100.46 | G3: No entertainment expenses included and all tax deductible
A4: Per TB | C4: =SUM(E:E) -> 61100.46 | T4: AU001 | U4: =SUMIF($A$10:$A$23973,"AU001",U9:U23972) -> 0
A5: Variance | C5: =C3-C4 -> 0 | T5: AU052 | U5: =SUMIF($A$10:$A$23974,"AU052",U9:U23973) -> 0
AC6: Income tax purposes
A7: BUSINESS_UNIT_CODE | B7: OPERATING_UNIT_CODE | C7: ACCOUNT_CODE | D7: DESCRIPTION | E7: BASE_AMOUNT | F7: BASE_CURRENCY_CODE | G7: JOURNAL_DATE | H7: DESCR | I7: LINE_DESCR | J7: PURPOSE | K7: INVOICE_DESCR | L7: INVOICE_ID | M7: VENDOR_NAME | N7: EMPLOYEE_NAME | O7: CHARGE_DESCRIPTION | Q7: ABS | R7: Search Terms | S7: Tax Description | T7: ME? Y/N | U7: ME $ | V7: Not ME but other type of FB Y/N | W7: Not ME but other type of FB ==> $ | X7: Nets to Nil in GL accts | Y7: s58P M&I or Bus Exp - notFB | Z7: ME | AA7: Car FB - addn op costs | AB7: CP Exp FB | AC7: Capital expenditure | AD7: No FBT and not ded | AE7: Additional Comments
A8: AU001 | B8: AU032074 | C8: 5160008000 | D8: Promotional gifts | E8: 11806.55 | F8: AUQ | G8: 45523 | H8: AP Accruals | I8: INV-2383-AGEOR00 | K8: GeorgeTheFarmer_National_Aug_B | L8: INV-2383 | M8: GEORGE THE FARMER PTY LTD | Q8: =ABS(E8) -> 11806.55 | S8: books provided to clients - accept as promotional
A9: AU052 | B9: AU025091 | C9: 5160008000 | D9: Promotional gifts | E9: 10044.09 | F9: AUQ | G9: 45645 | H9: CCMS | I9: ExmannJ-Default Licensee Merch | K9: JPMorgan Run Shirt Invoice | M9: SCODY | Q9: =ABS(E9) -> 10044.09 | S9: Each shirt under $300
A10: AU001 | B10: AU032063 | C10: 5160008000 | D10: Promotional gifts | E10: 5394.45 | F10: AUQ | G10: 45630 | H10: AP Accruals | I10: INV-2508-AGEOR00 | K10: GTF_CNNSW_Books_Nov24 | L10: INV-2508 | M10: GEORGE THE FARMER PTY LTD | Q10: =ABS(E10) -> 5394.45 | S10: books provided to clients - accept as promotional
A11: AU001 | B11: AU010021 | C11: 5160008000 | D11: Promotional gifts | E11: 5304.69 | F11: AUQ | G11: 45637 | H11: AP Accruals | I11: 2738-ATURN01 | K11: Promotional merchandise - Rabo | L11: 2738 | M11: TURNKEY PROMOTIONS | Q11: =ABS(E11) -> 5304.69 | S11: Accept promotional
A12: AU052 | B12: AU010021 | C12: 5160008000 | D12: Promotional gifts | E12: 3049.09 | F12: AUQ | G12: 45642 | H12: CCMS | I12: BaylissK-Offshore Meals & Lodg | K12: New Starter Welcome Gifts | M12: SQ *LONG TRACK PANTRY ONL | Q12: =ABS(E12) -> 3049.09 | S12: Each item under $300
A13: AU001 | B13: AU032066 | C13: 5160008000 | D13: Promotional gifts | E13: 2987.75 | F13: AUQ | G13: 45630 | H13: AP Accruals | I13: INV-2508-AGEOR00 | K13: GTF_SA_Books_Nov24 | L13: INV-2508 | M13: GEORGE THE FARMER PTY LTD | Q13: =ABS(E13) -> 2987.75 | S13: books provided to clients - accept as promotional
A14: AU001 | B14: AU032067 | C14: 5160008000 | D14: Promotional gifts | E14: 2731.98 | F14: AUQ | G14: 45630 | H14: AP Accruals | I14: INV-2508-AGEOR00 | K14: GTF_WA_Books_Nov24 | L14: INV-2508 | M14: GEORGE THE FARMER PTY LTD | Q14: =ABS(E14) -> 2731.98 | S14: books provided to clients - accept as promotional
A15: AU001 | B15: AU032061 | C15: 5160008000 | D15: Promotional gifts | E15: 2719.16 | F15: AUQ | G15: 45630 | H15: AP Accruals | I15: INV-2508-AGEOR00 | K15: GTF_NQNT_Books_Nov24 | L15: INV-2508 | M15: GEORGE THE FARMER PTY LTD | Q15: =ABS(E15) -> 2719.16 | S15: books provided to clients - accept as promotional
A16: AU001 | B16: AU032064 | C16: 5160008000 | D16: Promotional gifts | E16: 2707.64 | F16: AUQ | G16: 45630 | H16: AP Accruals | I16: INV-2508-AGEOR00 | K16: GTF_Riverina_Books_Nov24 | L16: INV-2508 | M16: GEORGE THE FARMER PTY LTD | Q16: =ABS(E16) -> 2707.64 | S16: books provided to clients - accept as promotional
A17: AU001 | B17: AU032062 | C17: 5160008000 | D17: Promotional gifts | E17: 2707.63 | F17: AUQ | G17: 45630 | H17: AP Accruals | I17: INV-2508-AGEOR00 | K17: GTF_SQ_Books_Nov24 | L17: INV-2508 | M17: GEORGE THE FARMER PTY LTD | Q17: =ABS(E17) -> 2707.63 | S17: books provided to clients - accept as promotional
A18: AU001 | B18: AU032065 | C18: 5160008000 | D18: Promotional gifts | E18: 2707.63 | F18: AUQ | G18: 45630 | H18: AP Accruals | I18: INV-2508-AGEOR00 | K18: GTF_SVT_Books_Nov24 | L18: INV-2508 | M18: GEORGE THE FARMER PTY LTD | Q18: =ABS(E18) -> 2707.63 | S18: books provided to clients - accept as promotional
A19: AU001 | B19: AU036740 | C19: 5160008000 | D19: Promotional gifts | E19: 1979.87 | F19: AUQ | G19: 45449 | H19: AP Accruals | I19: 2397-ATURN01 | L19: 2397 | M19: TURNKEY PROMOTIONS | Q19: =ABS(E19) -> 1979.87
A20: AU052 | B20: AU010021 | C20: 5160008000 | D20: Promotional gifts | E20: 1808.18 | F20: AUQ | G20: 45642 | H20: CCMS | I20: BaylissK-Offshore Meals & Lodg | K20: New Starter Welcome Gift | M20: BEECHWORTH HONEY PTY L | Q20: =ABS(E20) -> 1808.18 | S20: Each item under $300
A21: AU052 | B21: AU070150 | C21: 5160008000 | D21: Promotional gifts | E21: 769.91 | F21: AUQ | G21: 45505 | H21: CCMS | I21: Haynest-Offshore Meals & Lodgi | K21: archibald gifts | M21: Koko Black QVB North | Q21: =ABS(E21) -> 769.91 | S21: Gifts - not provided to staff
A22: AU001 | B22: AU036740 | C22: 5160008000 | D22: Promotional gifts | E22: 664.69 | F22: AUQ | G22: 45567 | H22: AP Accruals | I22: 240822-ATURN01 | K22: Rabobank branded notebooks for | L22: 240822 | M22: TURNKEY PROMOTIONS | Q22: =ABS(E22) -> 664.69 | S22: Promotional - office supplies
A23: AU001 | B23: AU036746 | C23: 5160008000 | D23: Promotional gifts | E23: 500 | F23: AUQ | G23: 45532 | H23: FT24241V1B14 Darwin Comp | I23: FT24241015C6 Darwin Comp | Q23: =ABS(E23) -> 500
A24: AU001 | B24: AU036746 | C24: 5160008000 | D24: Promotional gifts | E24: 500 | F24: AUQ | G24: 45532 | H24: FT24241V1B14 Darwin Comp | I24: FT24241V1B14 Darwin Comp | Q24: =ABS(E24) -> 500
A25: AU052 | B25: AU030512 | C25: 5160008000 | D25: Promotional gifts | E25: 474.36 | F25: AUQ | G25: 45414 | H25: CCMS | I25: ArnoldS-Entertainment Expense | K25: Property Settlement Gift Boxes for: Doudles, Schaefers, Peters and Crettendens (Total $16.3m new biz | M25: LS PORT LINCOLN GOURM | Q25: =ABS(E25) -> 474.36 | S25: Under $300 - accept 58P
A26: AU052 | B26: AU030512 | C26: 5160008000 | D26: Promotional gifts | E26: 368.36 | F26: AUQ | G26: 45639 | H26: CCMS | I26: ArnoldS-Entertainment Expense | K26: Settlement gifts for Modra x 2 and Pope | M26: LS PORT LINCOLN GOURM | Q26: =ABS(E26) -> 368.36 | S26: Under $300 - accept 58P
A27: AU052 | B27: AU010029 | C27: 5160008000 | D27: Promotional gifts | E27: 199.41 | F27: AUQ | G27: 45637 | H27: CCMS | I27: SunT-Office Supplies | K27: 2025 graduates welcomes hamper - client products | M27: SP GALLO DAIRYLAND | Q27: =ABS(E27) -> 199.41 | S27: Under $300 - accept 58P
A28: AU052 | B28: AU010029 | C28: 5160008000 | D28: Promotional gifts | E28: 195 | F28: AUQ | G28: 45637 | H28: CCMS | I28: SunT-Offshore Meals & Lodging | K28: 2025 graduates welcomes hamper - client products | M28: RASPBERRYFARMCAFE.COM | Q28: =ABS(E28) -> 195 | S28: Under $300 - accept 58P
A29: AU052 | B29: AU071196 | C29: 5160008000 | D29: Promotional gifts | E29: 181.45 | F29: AUQ | G29: 45642 | H29: CCMS | I29: RigbyC-Default Licensee Mercha | K29: Baby Gift - Trang & Shaun Tupou | M29: CR QVB | Q29: =ABS(E29) -> 181.45 | S29: Under $300 - accept 58P
A30: AU052 | B30: AU030422 | C30: 5160008000 | D30: Promotional gifts | E30: 168.14 | F30: AUQ | G30: 45506 | H30: CCMS | I30: ADAMSC-Software | K30: Gift - for David Kemp for venue of Rabo Truck event | M30: OUTBACK TRADERS A | Q30: =ABS(E30) -> 168.14
A31: AU052 | B31: AU010029 | C31: 5160008000 | D31: Promotional gifts | E31: 152.45 | F31: AUQ | G31: 45637 | H31: CCMS | I31: SunT-Offshore Meals & Lodging | K31: 2025 graduates welcomes hamper - client products | M31: SQ *LONG TRACK PANTRY ONL | Q31: =ABS(E31) -> 152.45
A32: AU052 | B32: AU032053 | C32: 5160008000 | D32: Promotional gifts | E32: 150.26 | F32: AUQ | G32: 45475 | H32: AP Accruals | I32: INV-2327-AGEOR00 | L32: INV-2327 | M32: GEORGE THE FARMER PTY LTD | Q32: =ABS(E32) -> 150.26
A33: AU052 | B33: AU030422 | C33: 5160008000 | D33: Promotional gifts | E33: 136.36 | F33: AUQ | G33: 45502 | H33: CCMS | I33: ADAMSC-Other Personnel Expense | K33: Gift - Flowers for Lynda Kemp Truck event | M33: ENCHANTED FLOWERS MA | Q33: =ABS(E33) -> 136.36
A34: AU052 | B34: AU010029 | C34: 5160008000 | D34: Promotional gifts | E34: 112.62 | F34: AUQ | G34: 45637 | H34: CCMS | I34: SunT-Office Supplies | K34: 2025 graduates welcomes hamper - client products | M34: SP SHOPIFY-ASHGROVEC | Q34: =ABS(E34) -> 112.62
A35: AU052 | B35: AU010011 | C35: 5160008000 | D35: Promotional gifts | E35: 111.65 | F35: AUQ | G35: 45387 | H35: CCMS | I35: BeckettK-Printing | K35: Farewell Sign_RBAL Chair_RANZ Cocktail Evening (19 March 2024) | M35: KWIK KOPY CENTRAL CITY | Q35: =ABS(E35) -> 111.65 | S35: Accept - promotional
