Workbook

Sheet Summary
A1: Rabobank Australia
A2: FBT return for the year ended 31 March 2025
A3: WP4 - Entertainment sensitive GL Accounts for Jan 2025 to Mar 25 | E3: Tfrred to "WPE1 ME Summary - GL analysis ent accounts.xls" | P3: NOTE for ITR/HardCat ê
F4: =F29 -> 48484.75 | I4: =I29 -> 499.09 | P4: =P29 -> 3139.98 | Q4: =Q29 -> 5559.3
I5: Pty FB >$300 | P5: Income tax purposes
A6: Account# | B6: Account Description | C6: Per TB | D6: Tax Description | E6: ME? Y/N | F6: ME $ | G6: AU001 / MEC | H6: AU052 | I6: Not ME but other type of FB Y/N | J6: $ | K6: Nets to Nil in GL accts | L6: s58P M&I or Bus Exp - notFB | M6: ME | N6: Car FB - addn op costs | O6: CP Exp FB | P6: Capital expenditure | Q6: No FBT and not ded | R6: Additional Comments
A8: 5140001000 | B8: Training expenses | C8: 39393.88 | D8: Picked up in Tuition expese analysis - NFA
A9: 5140001010 | B9: External Training and Seminars | C9: 121158.59 | D9: No ME included. All tax deductible | E9: Y | F9: ='Ext Training'!V53 -> 0 | G9: ='Ext Training'!V4 -> 0 | H9: ='Ext Training'!V5 -> 0 | R9: Noted
A10: 5140001030 | B10: Training travel and lodging ex | C10: 60353.16 | D10: No ME included. All tax deductible | E10: N | F10: ='Training Trav&lodg'!V4+'Training Trav&lodg'!V5 -> 0 | G10: ='Training Trav&lodg'!V4 -> 0 | H10: ='Training Trav&lodg'!V5 -> 0 | R10: Noted
A11: 5160001000 | B11: Publicity/advertising | C11: 211952.47 | D11: No ME included. All tax deductible | E11: N | F11: ='Publicity&Advert''g'!U4+'Publicity&Advert''g'!U5 -> 0 | G11: ='Publicity&Advert''g'!U4 -> 0 | H11: ='Publicity&Advert''g'!U5 -> 0 | R11: Noted
A12: 5160006000 | B12: Opening jubilees own buildin | C12: 0 | D12: No expenses recorded | E12: N | F12: ='Open-Jubilees'!S4+'Open-Jubilees'!S5 -> 0 | G12: ='Open-Jubilees'!S4 -> 0 | H12: ='Open-Jubilees'!S5 -> 0 | R12: Noted
A13: 5160007000 | B13: Sponsoring | C13: 18398.38 | D13: Minor ME, some RE added back | E13: Y | F13: =Sponsoring!V3+Sponsoring!V4 -> 127.27 | G13: =Sponsoring!V3 -> 0 | H13: =Sponsoring!V4 -> 127.27 | Q13: =Sponsoring!AE4+Sponsoring!AE3 -> 0 | R13: Noted
A14: 5160008000 | B14: Promotional gifts | C14: 7059.24 | D14: No ME included. client gifts are exempt from FBT | E14: N | F14: ='Promo gifts'!U4+'Promo gifts'!U5 -> 0 | G14: ='Promo gifts'!U4 -> 0 | H14: ='Promo gifts'!U5 -> 0 | R14: Noted
A15: 5160010000 | B15: Marketing expense | C15: -4733.21 | D15: Includes meal entertainment subject to FBT using 50/50 method | E15: Y | F15: =Marketing!V2+Marketing!V3 -> 1340.71 | G15: =Marketing!V2 -> 0 | H15: =Marketing!V3 -> 1340.71 | R15: OK
A16: 5160011000 | B16: Business development | C16: 260399.01 | D16: Includes ME | E16: Y | F16: ='Bus Dev'!V3+'Bus Dev'!V4 -> 33301.99 | G16: ='Bus Dev'!V3 -> 8846.07 | H16: ='Bus Dev'!V4 -> 24455.92 | R16: OK
A17: 5160999000 | B17: Public relations | C17: 11669.68 | D17: No ME included. All tax deductible | E17: N | F17: ='PR exp'!V4+'PR exp'!V5 -> 0 | G17: ='PR exp'!V4 -> 0 | H17: ='PR exp'!V5 -> 0 | R17: Noted
A18: 5180003000 | B18: Advice Tax & Legal expenses | C18: 39168.87 | D18: Picked up in Invoices WPE3 expese analysis - NFA | E18: N | R18: Noted
A19: 5190001000 | B19: Contributions& club membership | C19: 36644.04 | D19: No ME included. All tax deductible | E19: N | F19: ='Club memship'!U3+'Club memship'!U4 -> 0 | G19: ='Club memship'!V3 -> 0 | H19: ='Club memship'!V4 -> 0 | R19: Noted
A20: 5200006000 | B20: Meeting costs | C20: 112631.6 | D20: Includes meal entertainment subject to FBT using 50/50 method | E20: Y | F20: ='Meeting costs'!V3+'Meeting costs'!V4 -> 12438.54 | G20: ='Meeting costs'!V3 -> 4862 | H20: ='Meeting costs'!V4 -> 7576.54 | R20: =SUM(R18:R19) -> 0
A21: 5200999000 | B21: Miscellaneous expenses | C21: -7588.44 | D21: No ME included. | E21: N | F21: ='Misc exp'!U4+'Misc exp'!U5 -> 0 | G21: ='Misc exp'!U4 -> 0 | H21: ='Misc exp'!U5 -> 0 | R21: Noted
A22: 5200999010 | B22: Sundry expenses | C22: 0 | D22: No expenses recorded | E22: Y | F22: =Sundry!V4+Sundry!V5 -> 0 | G22: =Sundry!V4 -> 0 | H22: =Sundry!V5 -> 0 | R22: Noted
A23: 5200999020 | B23: Miscellaneous expenses (2) | C23: 216944.09 | D23: Inlcudes ME and staff gifts which are exempt from FBT | E23: Y | F23: ='Misc exp (2)'!V2+'Misc exp (2)'!V3 -> 141.8 | G23: ='Misc exp (2)'!V2 -> 0 | H23: ='Misc exp (2)'!V3 -> 141.8 | I23: ='Misc exp (2)'!W4 -> 499.09 | P23: ='Misc exp (2)'!AD2+'Misc exp (2)'!AD3 -> 0 | Q23: ='Misc exp (2)'!AE2+'Misc exp (2)'!AE3 -> 5559.3 | R23: Noted
A24: 5900050000 | B24: Other non banking expenses | C24: 10292.09 | D24: No ME included. All tax deductible | E24: N | F24: ='Other non-bank exp'!U4+'Other non-bank exp'!U5 -> 0 | G24: ='Other non-bank exp'!U4 -> 0 | H24: ='Other non-bank exp'!U5 -> 0 | R24: OK
A25: 5100999000 | B25: Other office expenses | C25: 91319.73 | D25: Inlcudes ME, staff gifts which are exempt from FBT and capital expenditure | E25: Y | F25: ='Other exp'!V3+'Other exp'!V4 -> 1134.44 | G25: ='Other exp'!V3 -> 1063.33 | H25: ='Other exp'!V4 -> 71.11 | P25: ='Other exp'!AD3+'Other exp'!AD4 -> 3139.98 | Q25: ='Other exp'!AE3+'Other exp'!AE4 -> 0 | R25: OK
A26: 5190002000 | B26: Donations | C26: 9848.87 | D26: No ME | E26: N | F26: =Donations!V3+Donations!V4 -> 0 | R26: Noted
A27: 5160002000 | B27: Client periodicals/magazines | C27: 209.96 | D27: No ME | E27: N | F27: ='Client period'!V3+'Client period'!V4 -> 0 | R27: Noted
D29: Total | F29: =SUM(F7:F28) -> 48484.75 | G29: =SUM(G8:G25) -> 14771.4 | H29: =SUM(H8:H25) -> 33713.35 | I29: =SUM(I7:I28) -> 499.09 | J29: =SUM(J7:J28) -> 0 | K29: =SUM(K7:K28) -> 0 | L29: =SUM(L7:L28) -> 0 | M29: =SUM(M7:M28) -> 0 | N29: =SUM(N7:N28) -> 0 | O29: =SUM(O7:O28) -> 0 | P29: =SUM(P7:P28) -> 3139.98 | ... R29: =SUM(R7:R28) -> 0
M31: Prepared by | R31: Reviewed By
M32: LF: Queries dealt with and responses at WPE1. Largely agreed with questions raises but have not made major changes given stage of process. Agreed we need a separate GL account or something for food whilst travelling | R32: LF response to my queries noted and accept calc accordingly. AJL16/5

Sheet Ext Training
A1: Account Number | C1: =Summary!A9 -> 5140001010
A2: Account Name | C2: =Summary!B9 -> External Training and Seminars | H2: Notes: | S2: No ME included. All tax deductible
A3: GL Total | C3: 121158.59 | H3: Expenditure on university courses and other courses conferences attended by employees. These are not considered REAP but are in
A4: Per TB | C4: =SUM(E:E) -> 121158.59 | H4: relation to the employees current roles so would be otherwise deductible for income tax purposes. No FBT will apply to these expenses. | T4: AU001 | V4: =SUMIF($A$10:$A$23731,"AU001",V9:V23730) -> 0 | AC4: AU001 | AD4: =SUMIF($A$10:$A$23731,"AU001",AD9:AD23730) -> 0 | AE4: =SUMIF($A$10:$A$23731,"AU001",AE9:AE23730) -> 0
A5: Variance | C5: =C3-C4 -> 0 | T5: AU052 | V5: =SUMIF($A$10:$A$23732,"AU052",V9:V23731) -> 0 | AC5: AU052 | AD5: =SUMIF($A$10:$A$23732,"AU052",AD9:AD23731) -> 0 | AE5: =SUMIF($A$10:$A$23732,"AU052",AE9:AE23731) -> 0
AD6: Income tax purposes
A7: BUSINESS_UNIT_CODE | B7: OPERATING_UNIT_CODE | C7: ACCOUNT_CODE | D7: DESCRIPTION | E7: BASE_AMOUNT | F7: BASE_CURRENCY_CODE | G7: JOURNAL_DATE | H7: DESCR | I7: LINE_DESCR | J7: PURPOSE | K7: INVOICE_DESCR | L7: INVOICE_ID | M7: VENDOR_NAME | N7: EMPLOYEE_NAME | O7: CHARGE_DESCRIPTION | Q7: ABS | R7: Search Terms | S7: Tax Description | T7: ME? Y/N | U7: OU | V7: ME $ | W7: Not ME but other type of FB Y/N | X7: Not ME but other type of FB ==> $ | Y7: Nets to Nil in GL accts | Z7: s58P M&I or Bus Exp - notFB | AA7: ME | AB7: Car FB - addn op costs | AC7: CP Exp FB | AD7: Capital expenditure | AE7: No FBT and not ded | AF7: Additional Comments
A8: AU052 | B8: AU010029 | C8: 5140001010 | D8: External Training and Seminars | E8: -55000 | F8: AUQ | G8: 45658 | H8: ADP Monthly Invoice - Dec2024 | I8: Graduate development workshop | Q8: =ABS(E8) -> 55000
A9: AU052 | B9: AU010029 | C9: 5140001010 | D9: External Training and Seminars | E9: 55000 | F9: AUQ | G9: 45686 | H9: Rabobank CB Search Marketing | I9: Graduate development works | Q9: =ABS(E9) -> 55000
A10: AU052 | B10: AU010029 | C10: 5140001010 | D10: External Training and Seminars | E10: -55000 | F10: AUQ | G10: 45691 | H10: Rabobank CB Search Marketing | I10: Graduate development works | Q10: =ABS(E10) -> 55000
A11: AU052 | B11: AU030055 | C11: 5140001010 | D11: External Training and Seminars | E11: 53991.82 | F11: AUQ | G11: 45702 | H11: AP Accruals | I11: RABO-I0225236-OINCH01 | K11: CB AU LT Offsite | L11: RABO-I0225236 | M11: INCHIGO | Q11: =ABS(E11) -> 53991.82
A12: AU052 | B12: AU030055 | C12: 5140001010 | D12: External Training and Seminars | E12: 32601.11 | F12: AUQ | G12: 45691 | H12: AP Accruals | I12: INV-20619-AFINA09 | K12: FEP Enrolments CPD | L12: INV-20619 | M12: FINANCIAL EDUCATION PROFFESIONALS PTYLTD | Q12: =ABS(E12) -> 32601.11
A13: AU001 | B13: AU010029 | C13: 5140001010 | D13: External Training and Seminars | E13: 21793.51 | F13: AUQ | G13: 45692 | H13: AP Accruals | I13: 1255-ACAPP01 | K13: Graduate development program d | L13: 1255 | M13: CAPPFINITY PTY LTD | Q13: =ABS(E13) -> 21793.51
A14: AU001 | B14: AU010021 | C14: 5140001010 | D14: External Training and Seminars | E14: 10438.19 | F14: AUQ | G14: 45692 | H14: AP Accruals | I14: RABOB0060129-AHARR02 | K14: Furniture Hire for YELT BC1 | L14: RABOB0060129 | M14: HARRY THE HIRER | Q14: =ABS(E14) -> 10438.19
A15: AU052 | B15: AU030055 | C15: 5140001010 | D15: External Training and Seminars | E15: 8676.66 | F15: AUQ | G15: 45691 | H15: AP Accruals | I15: INV-20619-AFINA09 | K15: FEP Enrolments ACL CPD | L15: INV-20619 | M15: FINANCIAL EDUCATION PROFFESIONALS PTYLTD | Q15: =ABS(E15) -> 8676.66
A16: AU052 | B16: AU025104 | C16: 5140001010 | D16: External Training and Seminars | E16: 5737.51 | F16: AUQ | G16: 45691 | H16: AP Accruals | I16: INV-20619-AFINA09 | K16: FEP Enrolments CPD | L16: INV-20619 | M16: FINANCIAL EDUCATION PROFFESIONALS PTYLTD | Q16: =ABS(E16) -> 5737.51
A17: AU052 | B17: AU036742 | C17: 5140001010 | D17: External Training and Seminars | E17: 5061.95 | F17: AUQ | G17: 45677 | H17: AP Accruals | I17: INV-7143-ALANG01 | K17: Team strengths profiles | L17: INV-7143 | M17: LANGLEY GROUP PTY LTD | Q17: =ABS(E17) -> 5061.95
A18: AU001 | B18: AU010021 | C18: 5140001010 | D18: External Training and Seminars | E18: 2974.58 | F18: AUQ | G18: 45691 | H18: AP Accruals | I18: 33108063-01-AFOUR01 | K18: Hyatt Sydney First Deposit | L18: 33108063-01 | M18: EP2 MANAGEMENT TA HYATT REGENCY SYDNEY | Q18: =ABS(E18) -> 2974.58
A19: AU001 | B19: AU010021 | C19: 5140001010 | D19: External Training and Seminars | E19: 2974.58 | F19: AUQ | G19: 45709 | H19: AP Accruals | I19: 33108063-2-AFOUR01 | K19: YELT BC1 Venue deposit 2 | L19: 33108063-2 | M19: EP2 MANAGEMENT TA HYATT REGENCY SYDNEY | Q19: =ABS(E19) -> 2974.58
A20: AU001 | B20: AU010021 | C20: 5140001010 | D20: External Training and Seminars | E20: 2974.58 | F20: AUQ | G20: 45709 | H20: AP Accruals | I20: 33108063-3-AFOUR01 | K20: YELT BC 1 Venue Deposit 3 | L20: 33108063-3 | M20: EP2 MANAGEMENT TA HYATT REGENCY SYDNEY | Q20: =ABS(E20) -> 2974.58
A21: AU052 | B21: AU030055 | C21: 5140001010 | D21: External Training and Seminars | E21: 2794.08 | F21: AUQ | G21: 45691 | H21: AP Accruals | I21: INV-20619-AFINA09 | K21: FEP Enrolments RMs | L21: INV-20619 | M21: FINANCIAL EDUCATION PROFFESIONALS PTYLTD | Q21: =ABS(E21) -> 2794.08
A22: AU052 | B22: AU073158 | C22: 5140001010 | D22: External Training and Seminars | E22: 2600 | F22: AUQ | G22: 45691 | H22: AP Accruals | I22: INV-20619-AFINA09 | K22: FEP Enrolment, S Laidlow | L22: INV-20619 | M22: FINANCIAL EDUCATION PROFFESIONALS PTYLTD | Q22: =ABS(E22) -> 2600
A23: AU052 | B23: AU010021 | C23: 5140001010 | D23: External Training and Seminars | E23: 2181.36 | F23: AUQ | G23: 45701 | H23: AP Accruals | I23: INV-01748-AWESN00 | K23: Photography for YELT BC 1 | L23: INV-01748 | M23: WES NEL PHOTOGRAPHY PTY LTD | Q23: =ABS(E23) -> 2181.36
A24: AU052 | B24: AU070150 | C24: 5140001010 | D24: External Training and Seminars | E24: 1849 | F24: AUQ | G24: 45733 | H24: CCMS | I24: BARRACLOUGHD-Default Licensee | J24: Food and Grocery Australia 2025 Registration | O24: EZI*AUSTRALIAN FOOD &/828834783 | Q24: =ABS(E24) -> 1849
A25: AU052 | B25: AU030055 | C25: 5140001010 | D25: External Training and Seminars | E25: 1529.55 | F25: AUQ | G25: 45734 | H25: CCMS | I25: ArnottC1-Default Licensee Merc | J25: APLMA Financial Modelling Course | O25: WWW.APLMA.COM | Q25: =ABS(E25) -> 1529.55
A26: AU052 | B26: AU030055 | C26: 5140001010 | D26: External Training and Seminars | E26: 1529.55 | F26: AUQ | G26: 45744 | H26: CCMS | I26: KilbyJ-Default Licensee Mercha | J26: Staff Training - James Kilby | O26: WWW.APLMA.COM | Q26: =ABS(E26) -> 1529.55
A27: AU052 | B27: AU070150 | C27: 5140001010 | D27: External Training and Seminars | E27: 1510.11 | F27: AUQ | G27: 45701 | H27: AP Accruals | I27: INV-7231-ALANG01 | K27: Offsite | L27: INV-7231 | M27: LANGLEY GROUP PTY LTD | Q27: =ABS(E27) -> 1510.11
A28: AU052 | B28: AU071196 | C28: 5140001010 | D28: External Training and Seminars | E28: 1294.38 | F28: AUQ | G28: 45701 | H28: AP Accruals | I28: INV-7231-ALANG01 | K28: Offsite | L28: INV-7231 | M28: LANGLEY GROUP PTY LTD | Q28: =ABS(E28) -> 1294.38
A29: AU052 | B29: AU025104 | C29: 5140001010 | D29: External Training and Seminars | E29: 1185 | F29: AUQ | G29: 45666 | H29: AP Accruals | I29: INV-20336-AFINA09 | K29: FEP Enrolments | L29: INV-20336 | M29: FINANCIAL EDUCATION PROFFESIONALS PTYLTD | Q29: =ABS(E29) -> 1185
A30: AU052 | B30: AU025104 | C30: 5140001010 | D30: External Training and Seminars | E30: 1185 | F30: AUQ | G30: 45729 | H30: AP Accruals | I30: INV-20841-AFINA09 | K30: FEP- Generic Knowledge and Dep | L30: INV-20841 | M30: FINANCIAL EDUCATION PROFFESIONALS PTYLTD | Q30: =ABS(E30) -> 1185
A31: AU052 | B31: AU025080 | C31: 5140001010 | D31: External Training and Seminars | E31: 948.44 | F31: AUQ | G31: 45679 | H31: 2220181-ATELU01 | I31: 8025670-OINTE03 | Q31: =ABS(E31) -> 948.44
A32: AU052 | B32: AU025080 | C32: 5140001010 | D32: External Training and Seminars | E32: 948.44 | F32: AUQ | G32: 45711 | H32: 90848234-ADIME01 | I32: 8025670-OINTE03 | Q32: =ABS(E32) -> 948.44
A33: AU052 | B33: AU025080 | C33: 5140001010 | D33: External Training and Seminars | E33: 948.44 | F33: AUQ | G33: 45734 | H33: 113522301-17/07/24-ACGUW05 | I33: 8025670-OINTE03 | Q33: =ABS(E33) -> 948.44
A34: AU052 | B34: AU070150 | C34: 5140001010 | D34: External Training and Seminars | E34: 915.3 | F34: AUQ | G34: 45744 | H34: CCMS | I34: Haynest-Software | J34: 3 tickets to the Agfood Fund conf. | O34: AGFOOD FUND PTY LTD | Q34: =ABS(E34) -> 915.3
A35: AU052 | B35: AU070150 | C35: 5140001010 | D35: External Training and Seminars | E35: 793.1 | F35: AUQ | G35: 45734 | H35: CCMS | I35: LaoV-Default Licensee Merchant | J35: APLMA - Advanced Documentation Course | O35: WWW.APLMA.COM | Q35: =ABS(E35) -> 793.1
A36: AU052 | B36: AU073158 | C36: 5140001010 | D36: External Training and Seminars | E36: 767 | F36: AUQ | G36: 45701 | H36: AP Accruals | I36: INV-7231-ALANG01 | K36: Offsite | L36: INV-7231 | M36: LANGLEY GROUP PTY LTD | Q36: =ABS(E36) -> 767
A37: AU052 | B37: AU070150 | C37: 5140001010 | D37: External Training and Seminars | E37: 630.55 | F37: AUQ | G37: 45734 | H37: CCMS | I37: CookM-Entertainment Expense | J37: ticket to the NTCA | O37: AA&P EVENTS | Q37: =ABS(E37) -> 630.55
A38: AU052 | B38: AU074251 | C38: 5140001010 | D38: External Training and Seminars | E38: 606.78 | F38: AUQ | G38: 45701 | H38: AP Accruals | I38: INV-7231-ALANG01 | K38: Offsite | L38: INV-7231 | M38: LANGLEY GROUP PTY LTD | Q38: =ABS(E38) -> 606.78
A39: AU052 | B39: AU010023 | C39: 5140001010 | D39: External Training and Seminars | E39: 600 | F39: AUQ | G39: 45735 | H39: CCMS | I39: SchofieldL-Default Licensee Me | J39: Advanced LSL Training - Karenanne O'Neill | O39: THE ASSOCIATION FOR PA/631213524720 | Q39: =ABS(E39) -> 600
A40: AU052 | B40: AU030055 | C40: 5140001010 | D40: External Training and Seminars | E40: 570 | F40: AUQ | G40: 45729 | H40: AP Accruals | I40: INV-20841-AFINA09 | K40: FEP - RG146 Tier 2 Deposits (E | L40: INV-20841 | M40: FINANCIAL EDUCATION PROFFESIONALS PTYLTD | Q40: =ABS(E40) -> 570
...

Sheet Training Trav&lodg
A1: Account Number | C1: =Summary!A10 -> 5140001030
A2: Account Name | C2: =Summary!B10 -> Training travel and lodging ex | G2: Notes: | S2: No ME included. All tax deductible
A3: GL Total | C3: 60353.16 | G3: Expenditure on university courses and other courses conferences attended by employees. These are not considered REAP but are in
A4: Per TB | C4: =SUM(E:E) -> 60353.16 | G4: relation to the employees current roles so would be otherwise deductible for income tax purposes. No FBT will apply to these expenses. | T4: AU001 | V4: =SUMIF($A$10:$A$23974,"AU001",V9:V23973) -> 0
A5: Variance | C5: =C3-C4 -> 0 | T5: AU052 | V5: =SUMIF($A$10:$A$23975,"AU052",V9:V23974) -> 0
AD6: Income tax purposes
A7: BUSINESS_UNIT_CODE | B7: OPERATING_UNIT_CODE | C7: ACCOUNT_CODE | D7: DESCRIPTION | E7: BASE_AMOUNT | F7: BASE_CURRENCY_CODE | G7: JOURNAL_DATE | H7: DESCR | I7: LINE_DESCR | J7: PURPOSE | K7: INVOICE_DESCR | L7: INVOICE_ID | M7: VENDOR_NAME | N7: EMPLOYEE_NAME | O7: CHARGE_DESCRIPTION | Q7: ABS | R7: Search Terms | S7: Tax Description | T7: ME? Y/N | U7: OU | V7: ME $ | W7: Not ME but other type of FB Y/N | X7: Not ME but other type of FB ==> $ | Y7: Nets to Nil in GL accts | Z7: s58P M&I or Bus Exp - notFB | AA7: ME | AB7: Car FB - addn op costs | AC7: CP Exp FB | AD7: Capital expenditure | AE7: No FBT and not ded | AF7: Additional Comments
A8: AU001 | B8: AU030510 | C8: 5140001030 | D8: Training travel and lodging ex | E8: 50879.85 | F8: AUQ | G8: 45663 | H8: AP Accruals | I8: 1009009-ABRID00 | K8: SANTNWV Offsite Deposit Feb 25 | L8: 1009009 | M8: BRIDGEPORT HOTEL | Q8: =ABS(E8) -> 50879.85
A9: AU052 | B9: AU036750 | C9: 5140001030 | D9: Training travel and lodging ex | E9: 1823.51 | F9: AUQ | G9: 45670 | H9: AP Accruals | I9: EEC-1160-EBRAD02 | K9: Hotel | L9: EEC-1160 | M9: ADAM BRADLEY | Q9: =ABS(E9) -> 1823.51
A10: AU001 | B10: AU070150 | C10: 5140001030 | D10: Training travel and lodging ex | E10: 1371.24 | F10: AUQ | G10: 45664 | H10: AP Accruals | I10: RABO-17/12/24-AINTE35 | K10: LT offsite accommodation | L10: RABO-17/12/24 | M10: INTERCONTINENTAL SYDNEY DOUBLE BAY | Q10: =ABS(E10) -> 1371.24
A11: AU001 | B11: AU073158 | C11: 5140001030 | D11: Training travel and lodging ex | E11: 1371.24 | F11: AUQ | G11: 45664 | H11: AP Accruals | I11: RABO-17/12/24-AINTE35 | K11: LT offsite accommodation | L11: RABO-17/12/24 | M11: INTERCONTINENTAL SYDNEY DOUBLE BAY | Q11: =ABS(E11) -> 1371.24
A12: AU001 | B12: AU074251 | C12: 5140001030 | D12: Training travel and lodging ex | E12: 1369.6 | F12: AUQ | G12: 45664 | H12: AP Accruals | I12: RABO-17/12/24-AINTE35 | K12: LT offsite accommodation | L12: RABO-17/12/24 | M12: INTERCONTINENTAL SYDNEY DOUBLE BAY | Q12: =ABS(E12) -> 1369.6
A13: AU001 | B13: AU071196 | C13: 5140001030 | D13: Training travel and lodging ex | E13: 1298.53 | F13: AUQ | G13: 45664 | H13: AP Accruals | I13: RABO-17/12/24-AINTE35 | K13: LT offsite accommodation | L13: RABO-17/12/24 | M13: INTERCONTINENTAL SYDNEY DOUBLE BAY | Q13: =ABS(E13) -> 1298.53
A14: AU052 | B14: AU061134 | C14: 5140001030 | D14: Training travel and lodging ex | E14: 829 | F14: AUQ | G14: 45720 | H14: AP Accruals | I14: 20250224-ACROW18 | K14: Crown Plaza Terrigal | L14: 20250224 | M14: CROWNE PLAZA TERRIGAL PACIFIC | Q14: =ABS(E14) -> 829
A15: AU001 | B15: AU032053 | C15: 5140001030 | D15: Training travel and lodging ex | E15: 463.01 | F15: AUQ | G15: 45727 | H15: AP Accruals | I15: CEC-14-ASPRI00 | K15: Return flights for NQNT CC mem | L15: CEC-14 | M15: SPRINGDALE LAND AND CATTLE CO | Q15: =ABS(E15) -> 463.01
A16: AU052 | B16: AU030055 | C16: 5140001030 | D16: Training travel and lodging ex | E16: 442.33 | F16: AUQ | G16: 45720 | H16: AP Accruals | I16: EEC-1312-EHOWA01 | K16: VICTAS offsite accommodation, | L16: EEC-1312 | Q16: =ABS(E16) -> 442.33
A17: AU052 | B17: AU036750 | C17: 5140001030 | D17: Training travel and lodging ex | E17: 325.53 | F17: AUQ | G17: 45670 | H17: AP Accruals | I17: EEC-1160-EBRAD02 | K17: Transport | L17: EEC-1160 | Q17: =ABS(E17) -> 325.53
A18: AU052 | B18: AU030310 | C18: 5140001030 | D18: Training travel and lodging ex | E18: 133.64 | F18: AUQ | G18: 45735 | H18: AP Accruals | I18: EEC-1430-EHARR00 | K18: Uber to training | L18: EEC-1430 | Q18: =ABS(E18) -> 133.64
A19: AU052 | B19: AU030710 | C19: 5140001030 | D19: Training travel and lodging ex | E19: 38.18 | F19: AUQ | G19: 45727 | H19: CCMS | I19: MccullochB-Company Car Parking | J19: Parking while at airport on training course | M19: Launceston Airport | Q19: =ABS(E19) -> 38.18
A20: AU052 | B20: AU030316 | C20: 5140001030 | D20: Training travel and lodging ex | E20: 7.5 | F20: AUQ | G20: 45673 | H20: CCMS | I20: WilsonE3-Airfares | J20: Egenica Booking Fee for Mt Gambier | M20: EGEN*AUSI142601669/AUBI2024348538423/AUBI2024348538423010 | Q20: =ABS(E20) -> 7.5

Sheet Publicity&Advert'g
A1: Account Number | C1: =Summary!A11 -> 5160001000
A2: Account Name | C2: =Summary!B11 -> Publicity/advertising | H2: Notes: | R2: No ME included. All tax deductible
A3: GL Total | C3: 211952.47 | H3: Rabobank truck expenses have been treated as deductible on the basis that they are a marketing expense under s8-1 | AB3: AU001 | AC3: =SUMIF($A$9:$A$175,"AU001",AC8:AC175) -> 0
A4: Per TB | C4: =SUM(E:E) -> 211952.47 | H4: No entertainment expenses included below - all relates to Rabotruck, marketing expences and items directly related to businss activities of Rabo | T4: AU001 | U4: =SUMIF($A$9:$A$175,"AU001",U8:U175) -> 0 | AB4: AU052 | AC4: =SUMIF($A$9:$A$175,"AU052",AC9:AC175) -> 0
A5: Variance | C5: =C3-C4 -> 0 | T5: AU052 | U5: =SUMIF($A$9:$A$175,"AU052",U8:U175) -> 0
AC6: Income tax purposes
A7: BUSINESS_UNIT_CODE | B7: OPERATING_UNIT_CODE | C7: ACCOUNT_CODE | D7: DESCRIPTION | E7: BASE_AMOUNT | F7: BASE_CURRENCY_CODE | G7: JOURNAL_DATE | H7: DESCR | I7: LINE_DESCR | J7: PURPOSE | K7: INVOICE_DESCR | L7: INVOICE_ID | M7: VENDOR_NAME | N7: EMPLOYEE_NAME | O7: CHARGE_DESCRIPTION | Q7: ABS | R7: Search Terms | S7: Tax Description | T7: ME? Y/N | U7: ME $ | V7: Not ME but other type of FB Y/N | W7: Not ME but other type of FB ==> $ | X7: Nets to Nil in GL accts | Y7: s58P M&I or Bus Exp - notFB | Z7: ME | AA7: Car FB - addn op costs | AB7: CP Exp FB | AC7: Capital expenditure | AD7: No FBT and not ded | AE7: Additional Comments
A8: AU001 | B8: AU032051 | C8: 5160001000 | D8: Publicity/advertising | E8: -242000 | F8: AUQ | G8: Wednesday, 1 January 2025 | H8: RaboTruck Operation (MNGT fee) | I8: Rabobank ROS Paid Media-Dec24 | Q8: =ABS(E8) -> 242000
A9: AU001 | B9: AU032046 | C9: 5160001000 | D9: Publicity/advertising | E9: -107045.4 | F9: AUQ | G9: Wednesday, 1 January 2025 | H9: RaboTruck Operation (MNGT fee) | I9: Rabo CB Paid Media-Brand-Oct24 | Q9: =ABS(E9) -> 107045.4
A10: AU001 | B10: AU032046 | C10: 5160001000 | D10: Publicity/advertising | E10: 107045.4 | F10: AUQ | G10: Wednesday, 29 January 2025 | H10: Rabobank CB Search Marketing | I10: Rabobank CB Paid Media Campaig | Q10: =ABS(E10) -> 107045.4
A11: AU001 | B11: AU032046 | C11: 5160001000 | D11: Publicity/advertising | E11: -107045.4 | F11: AUQ | G11: Monday, 3 February 2025 | H11: Rabobank CB Search Marketing | I11: Rabobank CB Paid Media Campaig | Q11: =ABS(E11) -> 107045.4
A12: AU001 | B12: AU032046 | C12: 5160001000 | D12: Publicity/advertising | E12: 106819.63 | F12: AUQ | G12: Wednesday, 19 February 2025 | H12: AP Accruals | I12: INV-14881-ABRYA02 | K12: 2024 accrual - CB brand campai | L12: INV-14881 | M12: BRYANT AND BROTHERS PTY LTD TA SPARRO | Q12: =ABS(E12) -> 106819.63
A13: AU001 | B13: AU032051 | C13: 5160001000 | D13: Publicity/advertising | E13: 92477.9 | F13: AUQ | G13: Wednesday, 29 January 2025 | H13: Rabobank CB Search Marketing | I13: Rabobank ROS Paid Media - Sear | Q13: =ABS(E13) -> 92477.9
A14: AU001 | B14: AU032051 | C14: 5160001000 | D14: Publicity/advertising | E14: -92477.9 | F14: AUQ | G14: Monday, 3 February 2025 | H14: Rabobank CB Search Marketing | I14: Rabobank ROS Paid Media - Sear | Q14: =ABS(E14) -> 92477.9
A15: AU001 | B15: AU032051 | C15: 5160001000 | D15: Publicity/advertising | E15: 92472.04 | F15: AUQ | G15: Wednesday, 19 February 2025 | H15: AP Accruals | I15: INV-14992-ABRYA02 | K15: 2024 accrual - ROS search mark | L15: INV-14992 | M15: BRYANT AND BROTHERS PTY LTD TA SPARRO | Q15: =ABS(E15) -> 92472.04
A16: AU001 | B16: AU032051 | C16: 5160001000 | D16: Publicity/advertising | E16: 90772.74 | F16: AUQ | G16: Wednesday, 29 January 2025 | H16: Rabobank CB Search Marketing | I16: Rabobank ROS Paid Media - Aff | Q16: =ABS(E16) -> 90772.74
A17: AU001 | B17: AU032051 | C17: 5160001000 | D17: Publicity/advertising | E17: -90772.74 | F17: AUQ | G17: Monday, 3 February 2025 | H17: Rabobank CB Search Marketing | I17: Rabobank ROS Paid Media - Aff | Q17: =ABS(E17) -> 90772.74
A18: AU001 | B18: AU032051 | C18: 5160001000 | D18: Publicity/advertising | E18: 90766.96 | F18: AUQ | G18: Wednesday, 19 February 2025 | H18: AP Accruals | I18: INV-14999-ABRYA02 | K18: 2024 accrual - ROS paid media | L18: INV-14999 | M18: BRYANT AND BROTHERS PTY LTD TA SPARRO | Q18: =ABS(E18) -> 90766.96
A19: AU001 | B19: AU032046 | C19: 5160001000 | D19: Publicity/advertising | E19: 66748.92 | F19: AUQ | G19: Monday, 3 March 2025 | H19: AP Accruals | I19: INV192145-AKG2P00 | K19: Brand Health - Invoice 2 | L19: INV192145 | M19: KISIMUL HOLDINGS PTY LTD | Q19: =ABS(E19) -> 66748.92
A20: AU001 | B20: AU036742 | C20: 5160001000 | D20: Publicity/advertising | E20: -65000 | F20: AUQ | G20: Wednesday, 1 January 2025 | H20: RaboTruck Operation (MNGT fee) | I20: Brand Health Survey - question | Q20: =ABS(E20) -> 65000
A21: AU001 | B21: AU036742 | C21: 5160001000 | D21: Publicity/advertising | E21: 65000 | F21: AUQ | G21: Wednesday, 29 January 2025 | H21: Rabobank CB Search Marketing | I21: Brand Health Survey - question | Q21: =ABS(E21) -> 65000
A22: AU001 | B22: AU036742 | C22: 5160001000 | D22: Publicity/advertising | E22: -65000 | F22: AUQ | G22: Monday, 3 February 2025 | H22: Rabobank CB Search Marketing | I22: Brand Health Survey - question | Q22: =ABS(E22) -> 65000
A23: AU001 | B23: AU036742 | C23: 5160001000 | D23: Publicity/advertising | E23: 63705.66 | F23: AUQ | G23: Tuesday, 18 February 2025 | H23: AP Accruals | I23: INV192133-AKG2P00 | K23: CB Brand Health Australia Invo | L23: INV192133 | M23: KISIMUL HOLDINGS PTY LTD | Q23: =ABS(E23) -> 63705.66
A24: AU001 | B24: AU032046 | C24: 5160001000 | D24: Publicity/advertising | E24: -61340.4 | F24: AUQ | G24: Wednesday, 1 January 2025 | H24: RaboTruck Operation (MNGT fee) | I24: The Land advertsing camp(NSW) | Q24: =ABS(E24) -> 61340.4
A25: AU001 | B25: AU032046 | C25: 5160001000 | D25: Publicity/advertising | E25: 61211.03 | F25: AUQ | G25: Tuesday, 7 January 2025 | H25: AP Accruals | I25: INV-14878-ABRYA02 | K25: NSW always on campaign medaia | L25: INV-14878 | M25: BRYANT AND BROTHERS PTY LTD TA SPARRO | Q25: =ABS(E25) -> 61211.03
A26: AU001 | B26: AU032046 | C26: 5160001000 | D26: Publicity/advertising | E26: -34777.19 | F26: AUQ | G26: Wednesday, 1 January 2025 | H26: RaboTruck Operation (MNGT fee) | I26: RaboTruck Operation (MNGT fee) | Q26: =ABS(E26) -> 34777.19
A27: AU001 | B27: AU032046 | C27: 5160001000 | D27: Publicity/advertising | E27: 34703.84 | F27: AUQ | G27: Tuesday, 7 January 2025 | H27: AP Accruals | I27: RABO2025/1-ASOLU01 | K27: RaboTruck Operation Q1 (Manage | L27: RABO2025/1 | M27: SOLUTION ENTERTAINMENT | Q27: =ABS(E27) -> 34703.84
A28: AU001 | B28: AU032046 | C28: 5160001000 | D28: Publicity/advertising | E28: 34650 | F28: AUQ | G28: Wednesday, 29 January 2025 | H28: Rabobank CB Search Marketing | I28: Nuffield Scholar Sponsorship | Q28: =ABS(E28) -> 34650
A29: AU001 | B29: AU032046 | C29: 5160001000 | D29: Publicity/advertising | E29: -34650 | F29: AUQ | G29: Monday, 3 February 2025 | H29: Rabobank CB Search Marketing | I29: Nuffield Scholar Sponsorship | Q29: =ABS(E29) -> 34650
A30: AU001 | B30: AU036740 | C30: 5160001000 | D30: Publicity/advertising | E30: 32997.9 | F30: AUQ | G30: Monday, 3 February 2025 | H30: AP Accruals | I30: 04001932-AFINA00 | K30: FAAA Roadshow sponsorship x 6 | L30: 4001932 | M30: FINANCIAL ADVICE ASSOCIATION | Q30: =ABS(E30) -> 32997.9
A31: AU001 | B31: AU032051 | C31: 5160001000 | D31: Publicity/advertising | E31: -30051 | F31: AUQ | G31: Wednesday, 1 January 2025 | H31: RaboTruck Operation (MNGT fee) | I31: Rabo Paid Media Reta Fee-Dec24 | Q31: =ABS(E31) -> 30051
A32: AU001 | B32: AU032051 | C32: 5160001000 | D32: Publicity/advertising | E32: 30048.8 | F32: AUQ | G32: Wednesday, 29 January 2025 | H32: Rabobank CB Search Marketing | I32: Rabobank Paid Media Retainer | Q32: =ABS(E32) -> 30048.8
A33: AU001 | B33: AU032051 | C33: 5160001000 | D33: Publicity/advertising | E33: -30048.8 | F33: AUQ | G33: Monday, 3 February 2025 | H33: Rabobank CB Search Marketing | I33: Rabobank Paid Media Retainer | Q33: =ABS(E33) -> 30048.8
A34: AU001 | B34: AU032051 | C34: 5160001000 | D34: Publicity/advertising | E34: 30046.89 | F34: AUQ | G34: Tuesday, 18 February 2025 | H34: AP Accruals | I34: INV-14844-ABRYA02 | K34: 2024 accrual - Paid media agen | L34: INV-14844 | M34: BRYANT AND BROTHERS PTY LTD TA SPARRO | Q34: =ABS(E34) -> 30046.89
A35: AU052 | B35: AU032056 | C35: 5160001000 | D35: Publicity/advertising | E35: 29899.45 | F35: AUQ | G35: Monday, 3 March 2025 | H35: AP Accruals | I35: INVKYNAU2228-AKYNE00 | K35: Rural Confidence Survey 24/25 | L35: INVKYNAU2228 | M35: KYNETEC AUSTRALIA PTY LTD | Q35: =ABS(E35) -> 29899.45
A36: AU001 | B36: AU032046 | C36: 5160001000 | D36: Publicity/advertising | E36: -29636.06 | F36: AUQ | G36: Wednesday, 1 January 2025 | H36: RaboTruck Operation (MNGT fee) | I36: RaboTruck Operation (Proj Mgr) | Q36: =ABS(E36) -> 29636.06
A37: AU001 | B37: AU032046 | C37: 5160001000 | D37: Publicity/advertising | E37: 29573.55 | F37: AUQ | G37: Tuesday, 7 January 2025 | H37: AP Accruals | I37: RABO2025/4-ASOLU01 | K37: RaboTruck Operation Q1 (Projec | L37: RABO2025/4 | M37: SOLUTION ENTERTAINMENT | Q37: =ABS(E37) -> 29573.55
A38: AU001 | B38: AU032046 | C38: 5160001000 | D38: Publicity/advertising | E38: -27500 | F38: AUQ | G38: Wednesday, 1 January 2025 | H38: RaboTruck Operation (MNGT fee) | I38: Cattle Australia sponsorship | Q38: =ABS(E38) -> 27500
A39: AU001 | B39: AU032046 | C39: 5160001000 | D39: Publicity/advertising | E39: 27500 | F39: AUQ | G39: Wednesday, 29 January 2025 | H39: Rabobank CB Search Marketing | I39: Cattle Australia sponsorship | Q39: =ABS(E39) -> 27500
A40: AU001 | B40: AU032046 | C40: 5160001000 | D40: Publicity/advertising | E40: -27500 | F40: AUQ | G40: Monday, 3 February 2025 | H40: Rabobank CB Search Marketing | I40: Cattle Australia sponsorship | Q40: =ABS(E40) -> 27500
...

Sheet Open-Jubilees
A1: Account Number | C1: =Summary!A12 -> 5160006000
A2: Account Name | C2: =Summary!B12 -> Opening jubilees own buildin | G2: Notes:
A3: GL Total | C3: 0 | G3: No entertainment expenses
A4: Per TB | C4: =SUM(D:D) -> 0 | R4: AU001 | S4: =SUMIF($A$10:$A$23974,"AU001",S9:S23973) -> 0
A5: Variance | C5: =C3-C4 -> 0 | R5: AU052 | S5: =SUMIF($A$10:$A$23975,"AU052",S9:S23974) -> 0
AA6: Income tax purposes
A7: BUSINESS_UNIT_CODE | B7: ACCOUNT_CODE | C7: DESCRIPTION | D7: BASE_AMOUNT | E7: BASE_CURRENCY_CODE | F7: JOURNAL_DATE | G7: DESCR | H7: LINE_DESCR | I7: PURPOSE | J7: INVOICE_DESCR | K7: INVOICE_ID | L7: VENDOR_NAME | M7: EMPLOYEE_NAME | O7: ABS | P7: Search Terms | Q7: Tax Description | R7: ME? Y/N | S7: ME $ | T7: Not ME but other type of FB Y/N | U7: Not ME but other type of FB ==> $ | V7: Nets to Nil in GL accts | W7: s58P M&I or Bus Exp - notFB | X7: ME | Y7: Car FB - addn op costs | Z7: CP Exp FB | AA7: Capital expenditure | AB7: No FBT and not ded | AC7: Additional Comments

Sheet Promo gifts
A1: Account Number | C1: =Summary!A14 -> 5160008000
A2: Account Name | C2: =Summary!B14 -> Promotional gifts | G2: Notes: | S2: No ME included. All tax deductible
A3: GL Total | C3: 7059.24 | G3: No entertainment expenses included and all tax deductible
A4: Per TB | C4: =SUM(E:E) -> 7059.24 | T4: AU001 | U4: =SUMIF($A$10:$A$23973,"AU001",U9:U23972) -> 0
A5: Variance | C5: =C3-C4 -> 0 | T5: AU052 | U5: =SUMIF($A$10:$A$23974,"AU052",U9:U23973) -> 0
AC6: Income tax purposes
A7: BUSINESS_UNIT_CODE | B7: OPERATING_UNIT_CODE | C7: ACCOUNT_CODE | D7: DESCRIPTION | E7: BASE_AMOUNT | F7: BASE_CURRENCY_CODE | G7: JOURNAL_DATE | H7: DESCR | I7: LINE_DESCR | J7: PURPOSE | K7: INVOICE_DESCR | L7: INVOICE_ID | M7: VENDOR_NAME | N7: EMPLOYEE_NAME | O7: CHARGE_DESCRIPTION | Q7: ABS | R7: Search Terms | S7: Tax Description | T7: ME? Y/N | U7: ME $ | V7: Not ME but other type of FB Y/N | W7: Not ME but other type of FB ==> $ | X7: Nets to Nil in GL accts | Y7: s58P M&I or Bus Exp - notFB | Z7: ME | AA7: Car FB - addn op costs | AB7: CP Exp FB | AC7: Capital expenditure | AD7: No FBT and not ded | AE7: Additional Comments
A8: AU001 | B8: AU070150 | C8: 5160008000 | D8: Promotional gifts | E8: 451 | F8: AUQ | G8: 45737 | H8: AP Accruals | I8: 2852-ATURN01 | J8: Gift bags for WAB | L8: 2852 | O8: TURNKEY PROMOTIONS | Q8: =ABS(E8) -> 451 | S8: 50 bags - accept 58P
A9: AU052 | B9: AU071196 | C9: 5160008000 | D9: Promotional gifts | E9: 70.41 | F9: AUQ | G9: 45659 | H9: CCMS | I9: RigbyC-Office Supplies | J9: Maureen Wilde gift | O9: WOOLWORTHS/CNR 540 GEORGE | Q9: =ABS(E9) -> 70.41 | S9: 58P
A10: AU052 | B10: AU070150 | C10: 5160008000 | D10: Promotional gifts | E10: 1363.64 | F10: AUQ | G10: 45694 | H10: CCMS | I10: RigbyC-Default Licensee Mercha | J10: Ross Dawson - Global Food Forum TIckets | O10: TICKETS*THE AUSTRA/fs72t8tf | Q10: =ABS(E10) -> 1363.64 | S10: OK - for clients
A11: AU052 | B11: AU070150 | C11: 5160008000 | D11: Promotional gifts | E11: 177.27 | F11: AUQ | G11: 45694 | H11: CCMS | I11: RigbyC-Other Personnel Expense | J11: James Ashworth - Client Gift - Delia Sparkes Metcash | O11: SP LILAC AND WILLOW | Q11: =ABS(E11) -> 177.27 | S11: OK - for clients
A12: AU052 | B12: AU070150 | C12: 5160008000 | D12: Promotional gifts | E12: 99.01 | F12: AUQ | G12: 45723 | H12: CCMS | I12: RigbyC-Software | J12: Client Gift Kate Beddoe - Lunch and Learn | O12: SP LITTLE KOHA | Q12: =ABS(E12) -> 99.01 | S12: OK - for clients
A13: AU052 | B13: AU070150 | C13: 5160008000 | D13: Promotional gifts | E13: 2716.36 | F13: AUQ | G13: 45726 | H13: CCMS | I13: Haynest-Entertainment Expense | J13: WAB gifts - 36 wines | O13: CellarDoor.co | Q13: =ABS(E13) -> 2716.36 | S13: 58P
A14: AU052 | B14: AU030711 | C14: 5160008000 | D14: Promotional gifts | E14: 67.55 | F14: AUQ | G14: 45729 | H14: CCMS | I14: HumeH-Default Licensee Merchan | J14: Burbury Settlement Gift - wine glasses and card for hamper | O14: COCO BLUE | Q14: =ABS(E14) -> 67.55 | S14: OK - for clients
A15: AU052 | B15: AU030711 | C15: 5160008000 | D15: Promotional gifts | E15: 40.91 | F15: AUQ | G15: 45729 | H15: CCMS | I15: HumeH-Offshore Meals & Lodging | J15: Wine for Burburys | O15: SQ *MILTON VINEYARD | Q15: =ABS(E15) -> 40.91 | S15: OK - for clients
A16: AU052 | B16: AU032054 | C16: 5160008000 | D16: Promotional gifts | E16: 183.09 | F16: AUQ | G16: 45743 | H16: CCMS | I16: DoupeJ-Office Supplies | J16: Gifts for 2 clients for Sustainability Offsite | O16: SQ *HAIGH'S THE STRAND AR | Q16: =ABS(E16) -> 183.09 | S16: OK - for clients
A17: AU052 | B17: AU070150 | C17: 5160008000 | D17: Promotional gifts | E17: 1890 | F17: AUQ | G17: 45744 | H17: CCMS | I17: Haynest-Default Licensee Merch | J17: WAB shirt gifts | O17: R.M.Williams | Q17: =ABS(E17) -> 1890 | S17: 58P

Sheet Sponsoring
A1: Account Number | C1: =Summary!A13 -> 5160007000
A2: Account Name | C2: =Summary!B13 -> Sponsoring | G2: Notes:
A3: GL Total | C3: 18398.38 | G3: No entertainment expenses included and all tax deductible | T3: AU001 | V3: =SUMIF($A$10:$A$23974,"AU001",V8:V23972) -> 0 | AC3: AU001 | AD3: =SUMIF($A$10:$A$408,"AU001",AD8:AD407) -> 0 | AE3: =SUMIF($A$10:$A$408,"AU001",AE8:AE407) -> 0
A4: Per TB | C4: =SUM(E:E) -> 18398.38 | G4: Charity days/community days have not been treated as recreational activity (arguably does not meet ITAA definition) | T4: AU052 | V4: =SUMIF($A$10:$A$23975,"AU052",V8:V23973) -> 127.27 | AC4: AU052 | AD4: =SUMIF($A$10:$A$408,"AU052",AD9:AD407) -> 0 | AE4: =SUMIF($A$10:$A$408,"AU052",AE9:AE407) -> 0
A5: Variance | C5: =C3-C4 -> 0
AD6: Income tax purposes
A7: BUSINESS_UNIT_CODE | B7: OPERATING_UNIT_CODE | C7: ACCOUNT_CODE | D7: DESCRIPTION | E7: BASE_AMOUNT | F7: BASE_CURRENCY_CODE | G7: JOURNAL_DATE | H7: DESCR | I7: LINE_DESCR | J7: PURPOSE | K7: INVOICE_DESCR | L7: INVOICE_ID | M7: VENDOR_NAME | N7: EMPLOYEE_NAME | O7: CHARGE_DESCRIPTION | Q7: ABS | R7: Search Terms | S7: Tax Description | T7: ME? Y/N | U7: OU | V7: ME $ | W7: Not ME but other type of FB Y/N | X7: Not ME but other type of FB ==> $ | Y7: Nets to Nil in GL accts | Z7: s58P M&I or Bus Exp - notFB | AA7: ME | AB7: Car FB - addn op costs | AC7: CP Exp FB | AD7: Capital expenditure | AE7: No FBT and not ded | AF7: Additional Comments
A8: AU001 | B8: AU032063 | C8: 5160007000 | D8: Sponsoring | E8: 7500 | F8: AUQ | G8: 45719 | H8: AP Accruals | I8: ASCF-0078-AAUST86 | K8: NSW Client Council Sponsorship | L8: ASCF-0078 | M8: AUSTRALIAN SKIN CANCER FOUNDATION LTD | Q8: =ABS(E8) -> 7500
A9: AU001 | B9: AU032072 | C9: 5160007000 | D9: Sponsoring | E9: 9443.29 | F9: AUQ | G9: 45720 | H9: AP Accruals | I9: INV-1553-ARIDI01 | K9: 2024 Sponsorship of Riding for | L9: INV-1553 | M9: RIDING FOR THE DISABLED OF THE ACT INC | Q9: =ABS(E9) -> 9443.29
A10: AU001 | B10: AU032046 | C10: 5160007000 | D10: Sponsoring | E10: 400 | F10: AUQ | G10: 45723 | H10: AP Accruals | I10: 2060-ABOMB00 | K10: Bombala Show Society-Dog Trial | L10: 2060 | M10: BOMBALA EXHIBITION SOCIETY INC | Q10: =ABS(E10) -> 400
A11: AU052 | B11: AU030317 | C11: 5160007000 | D11: Sponsoring | E11: 127.27 | F11: AUQ | G11: 45706 | H11: CCMS | I11: BennettA-Entertainment Expense | J11: Gannon discussion group xmas drinks | M11: SQ *NERRENA CRICKET CLUB | Q11: =ABS(E11) -> 127.27 | S11: ME | T11: Y | U11: =B11 -> AU030317 | V11: =E11 -> 127.27
A12: AU052 | B12: AU030423 | C12: 5160007000 | D12: Sponsoring | E12: 500 | F12: AUQ | G12: 45707 | H12: CCMS | I12: KelleyM-Default Licensee Merch | J12: Sponsorship - Cotton Dinner | M12: TRYBOOKING*CHCGIA/219528771395 | Q12: =ABS(E12) -> 500
A13: AU052 | B13: AU030214 | C13: 5160007000 | D13: Sponsoring | E13: 427.82 | F13: AUQ | G13: 45734 | H13: CCMS | I13: HuntA-Contributions & Club Mem | J13: Parkes Ewe Comp Sponsorship | M13: Parkes Bowling Club | Q13: =ABS(E13) -> 427.82

Sheet Marketing
A1: Account Number | C1: =Summary!A15 -> 5160010000
A2: Account Name | C2: =Summary!B15 -> Marketing expense | H2: Notes: | T2: AU001 | V2: =SUMIF($A$8:$A$23958,"AU001",V8:V23958) -> 0
A3: GL Total | C3: -4733.21 | H3: All field day expenses have been treated as deductible | T3: AU052 | V3: =SUMIF($A$8:$A$23959,"AU052",V8:V23959) -> 1340.71
A4: Per TB | C4: =SUM(E:E) -> -4733.21 | H4: All branch Anniversary expenses have been treated as ME | V4: =V71+V3 -> 1340.71
A5: Variance | C5: =C3-C4 -> 0
AD6: Income tax purposes
A7: BUSINESS_UNIT_CODE | B7: OPERATING_UNIT_CODE | C7: ACCOUNT_CODE | D7: DESCRIPTION | E7: BASE_AMOUNT | F7: BASE_CURRENCY_CODE | G7: JOURNAL_DATE | H7: DESCR | I7: LINE_DESCR | J7: PURPOSE | K7: INVOICE_DESCR | L7: INVOICE_ID | M7: VENDOR_NAME | N7: EMPLOYEE_NAME | O7: CHARGE_DESCRIPTION | Q7: ABS | R7: Search Terms | S7: Tax Description | T7: ME? Y/N | U7: OU | V7: ME $ | W7: Not ME but other type of FB Y/N | X7: Not ME but other type of FB ==> $ | Y7: Nets to Nil in GL accts | Z7: s58P M&I or Bus Exp - notFB | AA7: ME | AB7: Car FB - addn op costs | AC7: CP Exp FB | AD7: Capital expenditure | AE7: No FBT and not ded | AF7: Additional Comments
A8: AU001 | B8: AU036740 | C8: 5160010000 | D8: Marketing expense | E8: 6599.58 | F8: AUQ | G8: 45677 | H8: AP Accruals | I8: AR001558-AAGRI25 | K8: Co hosting event with AgriFutu | L8: AR001558 | M8: AGRIFUTURES AUSTRALIA | Q8: =ABS(E8) -> 6599.58
A9: AU052 | B9: AU073158 | C9: 5160010000 | D9: Marketing expense | E9: 1565.5 | F9: AUQ | G9: 45705 | H9: CCMS | I9: OoiS-Default Licensee Merchant | J9: Wholesale SMS text to clients | O9: WholesaleSMS Pty Ltd | Q9: =ABS(E9) -> 1565.5
A10: AU052 | B10: AU030320 | C10: 5160010000 | D10: Marketing expense | E10: 1003.52 | F10: AUQ | G10: 45670 | H10: AP Accruals | I10: 14220-AHAMI04 | K10: Venue hire for client Christma | L10: 14220 | M10: HAMILTON PASTORAL AND AGRICULTURAL | Q10: =ABS(E10) -> 1003.52 | S10: ME | T10: Y | U10: =B10 -> AU030320 | V10: =E10 -> 1003.52
A11: AU052 | B11: AU073158 | C11: 5160010000 | D11: Marketing expense | E11: 909 | F11: AUQ | G11: 45677 | H11: CCMS | I11: OoiS-Default Licensee Merchant | J11: Wholesale SMS text to clients | O11: WholesaleSMS Pty Ltd | Q11: =ABS(E11) -> 909
A12: AU052 | B12: AU073158 | C12: 5160010000 | D12: Marketing expense | E12: 909 | F12: AUQ | G12: 45734 | H12: CCMS | I12: OoiS-Default Licensee Merchant | J12: Wholesale SMS text to clients | O12: WholesaleSMS Pty Ltd | Q12: =ABS(E12) -> 909
A13: AU001 | B13: AU030619 | C13: 5160010000 | D13: Marketing expense | E13: 819.8 | F13: AUQ | G13: 45664 | H13: AP Accruals | I13: 00000521-AWAGI03 | K13: Woolorama 2025: Young Judges S | L13: 00000521 | M13: WAGIN AGRICULTURAL SOCIETY INC | Q13: =ABS(E13) -> 819.8
A14: AU052 | B14: AU073158 | C14: 5160010000 | D14: Marketing expense | E14: 656.5 | F14: AUQ | G14: 45723 | H14: CCMS | I14: OoiS-Default Licensee Merchant | J14: Wholesale SMS text to clients | O14: WholesaleSMS Pty Ltd | Q14: =ABS(E14) -> 656.5
A15: AU052 | B15: AU073158 | C15: 5160010000 | D15: Marketing expense | E15: 656.5 | F15: AUQ | G15: 45744 | H15: CCMS | I15: OoiS-Default Licensee Merchant | J15: Wholesale SMS text to clients | O15: WholesaleSMS Pty Ltd | Q15: =ABS(E15) -> 656.5
A16: AU001 | B16: AU032061 | C16: 5160010000 | D16: Marketing expense | E16: 646.5 | F16: AUQ | G16: 45664 | H16: AP Accruals | I16: CEC-9-ASPUR00 | K16: NQNTClientCouncilMeeting_Towns | L16: CEC-9 | M16: SPURDLE FAMILY TRUST | Q16: =ABS(E16) -> 646.5
A17: AU001 | B17: AU030613 | C17: 5160010000 | D17: Marketing expense | E17: -500 | F17: AUQ | G17: 45665 | H17: YFFB-21 Wandel | I17: YFFB-10 Klug | Q17: =ABS(E17) -> 500
A18: AU001 | B18: AU030613 | C18: 5160010000 | D18: Marketing expense | E18: -500 | F18: AUQ | G18: 45665 | H18: YFFB-21 Wandel | I18: YFFB-11 Klug | Q18: =ABS(E18) -> 500
A19: AU001 | B19: AU030613 | C19: 5160010000 | D19: Marketing expense | E19: -500 | F19: AUQ | G19: 45665 | H19: YFFB-21 Wandel | I19: YFFB-18 Dare | Q19: =ABS(E19) -> 500
A20: AU001 | B20: AU030613 | C20: 5160010000 | D20: Marketing expense | E20: -500 | F20: AUQ | G20: 45665 | H20: YFFB-21 Wandel | I20: YFFB-19 Dare | Q20: =ABS(E20) -> 500
A21: AU001 | B21: AU030613 | C21: 5160010000 | D21: Marketing expense | E21: -500 | F21: AUQ | G21: 45665 | H21: YFFB-21 Wandel | I21: YFFB-21 Wandel | Q21: =ABS(E21) -> 500
A22: AU001 | B22: AU030613 | C22: 5160010000 | D22: Marketing expense | E22: -500 | F22: AUQ | G22: 45665 | H22: YFFB-21 Wandel | I22: YFFB-25 Partridge | Q22: =ABS(E22) -> 500
A23: AU001 | B23: AU030613 | C23: 5160010000 | D23: Marketing expense | E23: -500 | F23: AUQ | G23: 45665 | H23: YFFB-21 Wandel | I23: YFFB-26 Rowe | Q23: =ABS(E23) -> 500
A24: AU001 | B24: AU030613 | C24: 5160010000 | D24: Marketing expense | E24: -500 | F24: AUQ | G24: 45665 | H24: YFFB-21 Wandel | I24: YFFB-29 Newman | Q24: =ABS(E24) -> 500
A25: AU001 | B25: AU030613 | C25: 5160010000 | D25: Marketing expense | E25: -500 | F25: AUQ | G25: 45677 | H25: YFFB-20 Keeffe | I25: YFFB-12 Poole | Q25: =ABS(E25) -> 500
A26: AU001 | B26: AU030613 | C26: 5160010000 | D26: Marketing expense | E26: -500 | F26: AUQ | G26: 45677 | H26: YFFB-20 Keeffe | I26: YFFB-20 Keeffe | Q26: =ABS(E26) -> 500
A27: AU001 | B27: AU030613 | C27: 5160010000 | D27: Marketing expense | E27: -500 | F27: AUQ | G27: 45677 | H27: YFFB-20 Keeffe | I27: YFFB-22 Bradshaw | Q27: =ABS(E27) -> 500
A28: AU001 | B28: AU030613 | C28: 5160010000 | D28: Marketing expense | E28: -500 | F28: AUQ | G28: 45677 | H28: YFFB-20 Keeffe | I28: YFFB-23 Kenny | Q28: =ABS(E28) -> 500
... A57: AU001 | B57: AU030613 | C57: 5160010000 | D57: Marketing expense | E57: -500 | F57: AUQ | G57: 45740 | H57: YFFB-50 Dykes | I57: YFFB-50 Dykes | Q57: =ABS(E57) -> 500
A58: AU052 | B58: AU032053 | C58: 5160010000 | D58: Marketing expense | E58: 470.42 | F58: AUQ | G58: 45720 | H58: AP Accruals | I58: CEC-12-AANDR00 | K58: Return flights for Melissa Deg | L58: CEC-12 | M58: ANDREW AND MELISSA DEGUARA | Q58: =ABS(E58) -> 470.42
A59: AU001 | B59: AU032061 | C59: 5160010000 | D59: Marketing expense | E59: 344.2 | F59: AUQ | G59: 45665 | H59: AP Accruals | I59: CEC-10-AJMSL00 | K59: Return flights Richmond-Townsv | L59: CEC-10 | M59: JM AND SL BELLINGHAM | Q59: =ABS(E59) -> 344.2
A60: AU052 | B60: AU032046 | C60: 5160010000 | D60: Marketing expense | E60: 300 | F60: AUQ | G60: 45677 | H60: CCMS | I60: GruchyR-Default Licensee Merch | J60: cool room hire for Rabo Truck Xmas Moree | O60: JOCKS HIRE | Q60: =ABS(E60) -> 300 | S60: ME | T60: Y | U60: =B60 -> AU032046 | V60: =E60 -> 300
A61: AU052 | B61: AU030214 | C61: 5160010000 | D61: Marketing expense | E61: 186.27 | F61: AUQ | G61: 45664 | H61: CCMS | I61: RyanR-Other Personnel Expense | J61: RaboLive - Client Gift | O61: LS MARTHAS FOOD & HOME | Q61: =ABS(E61) -> 186.27
A62: AU001 | B62: AU030619 | C62: 5160010000 | D62: Marketing expense | E62: 168.93 | F62: AUQ | G62: 45721 | H62: AP Accruals | I62: 00000572-AWAGI03 | K62: Wagin Woolorama 2025: Addition | L62: 00000572 | M62: WAGIN AGRICULTURAL SOCIETY INC | Q62: =ABS(E62) -> 168.93
A63: AU052 | B63: AU032046 | C63: 5160010000 | D63: Marketing expense | E63: 129.55 | F63: AUQ | G63: 45677 | H63: CCMS | I63: TaylorF-Office Supplies | J63: Ice - Moree RaboTruck Event | O63: WOOLWORTHS/215 BALO ST | Q63: =ABS(E63) -> 129.55
A64: AU052 | B64: AU030214 | C64: 5160010000 | D64: Marketing expense | E64: 85.55 | F64: AUQ | G64: 45664 | H64: CCMS | I64: RyanR-Entertainment Expense | J64: RaboLive - Client Gift | O64: ORANGE CELLARS/153218026358 | Q64: =ABS(E64) -> 85.55
A65: AU052 | B65: AU032046 | C65: 5160010000 | D65: Marketing expense | E65: 66.4 | F65: AUQ | G65: 45677 | H65: CCMS | I65: TaylorF-Default Licensee Merch | J65: Lukcy door prizes - Moree RaboTruck event | O65: SMP*PR Interiors | Q65: =ABS(E65) -> 66.4
A66: AU052 | B66: AU030214 | C66: 5160010000 | D66: Marketing expense | E66: 50.83 | F66: AUQ | G66: 45719 | H66: CCMS | I66: RyanR-Default Licensee Merchan | J66: Branch Sponsorship | O66: SMP*Ricks Engraving a6b | Q66: =ABS(E66) -> 50.83
A67: AU052 | B67: AU032046 | C67: 5160010000 | D67: Marketing expense | E67: 49.73 | F67: AUQ | G67: 45677 | H67: CCMS | I67: TaylorF-Office Supplies | J67: Tea & Coffee Station - Moree RaboTruck event | O67: WOOLWORTHS/215 BALO ST | Q67: =ABS(E67) -> 49.73
A68: AU052 | B68: AU032046 | C68: 5160010000 | D68: Marketing expense | E68: 43.64 | F68: AUQ | G68: 45677 | H68: CCMS | I68: TaylorF-Airfares | J68: Lucky Door Prize - Moree RaboTruck Event | O68: TOURISM MOREE INC | Q68: =ABS(E68) -> 43.64
...

Sheet Bus Dev
A1: Account Number | C1: =Summary!A16 -> 5160011000
A2: Account Name | C2: =Summary!B16 -> Business development | G2: Notes:
A3: GL Total | C3: 260399.01 | G3: Marquees, furniture and other associated costs at field day events are a business expense and not a recreational event - treated as tax deductible and not subject to FBT | T3: AU001 | V3: =SUMIF($A$8:$A$23974,"AU001",V8:V23974) -> 8846.07
A4: Per TB | C4: =SUM(E:E) -> 260399.01 | G4: Sponsorship is deductible under s8-1 as it promotes the business and the expectation is that it will generate future business | T4: AU052 | V4: =SUMIF($A$8:$A$23974,"AU052",V8:V23974) -> 24455.92
A5: Variance | C5: =C3-C4 -> 0 | G5: Rabobank truck expenses have been treated as deductible on the basis that they are a marketing expense under s8-1. | V5: =SUM(V3:V4) -> 33301.99
G6: Field days include alcohol - but staff are not able to drink on jobs. Intention is to assist prospective clients or existing clients. Run sheets are available. Days usually wrap up mid afternoon. | AD6: Income tax purposes
A7: BUSINESS_UNIT_CODE | B7: OPERATING_UNIT_CODE | C7: ACCOUNT_CODE | D7: DESCRIPTION | E7: BASE_AMOUNT | F7: BASE_CURRENCY_CODE | G7: JOURNAL_DATE | H7: DESCR | I7: LINE_DESCR | J7: PURPOSE | K7: INVOICE_DESCR | L7: INVOICE_ID | M7: VENDOR_NAME | N7: EMPLOYEE_NAME | O7: CHARGE_DESCRIPTION | Q7: ABS | R7: Search Terms | S7: Tax Description | T7: ME? Y/N | U7: OU | V7: ME $ | W7: Not ME but other type of FB Y/N | X7: Not ME but other type of FB ==> $ | Y7: Nets to Nil in GL accts | Z7: s58P M&I or Bus Exp - notFB | AA7: ME | AB7: Car FB - addn op costs | AC7: CP Exp FB | AD7: Capital expenditure | AE7: No FBT and not ded | AF7: Additional Comments
A8: AU001 | B8: AU032046 | C8: 5160011000 | D8: Business development | E8: -34650 | F8: AUQ | G8: 45658 | H8: Nuffield Scholar Sponsorship | K8: Nuffield Scholar Sponsorship | Q8: =ABS(E8) -> 34650
A9: AU001 | B9: AU032046 | C9: 5160011000 | D9: Business development | E9: 34576.92 | F9: AUQ | G9: 45705 | H9: AP Accruals | I9: INV-10913-ANUFF00 | K9: Nuffield Australia Scholar Spo | L9: INV-10913 | M9: NUFFIELD AUSTRALIA | Q9: =ABS(E9) -> 34576.92
A10: AU001 | B10: AU032046 | C10: 5160011000 | D10: Business development | E10: 27442 | F10: AUQ | G10: 45709 | H10: AP Accruals | I10: INV-3384-ACATT03 | K10: Platinum Sponsorship - Cattle | L10: INV-3384 | M10: CATTLE AUSTRALIA | Q10: =ABS(E10) -> 27442
A11: AU001 | B11: AU032046 | C11: 5160011000 | D11: Business development | E11: 18660.56 | F11: AUQ | G11: 45664 | H11: AP Accruals | I11: RABO2025/6-ASOLU01 | K11: RaboTruck Gippsland event x 2 | L11: RABO2025/6 | M11: SOLUTION ENTERTAINMENT | Q11: =ABS(E11) -> 18660.56
A12: AU001 | B12: AU036740 | C12: 5160011000 | D12: Business development | E12: 14992.05 | F12: AUQ | G12: 45730 | H12: AP Accruals | I12: 2826-ATURN01 | K12: Deposit merchandise for the FA | L12: 2826 | M12: TURNKEY PROMOTIONS | Q12: =ABS(E12) -> 14992.05
A13: AU001 | B13: AU032046 | C13: 5160011000 | D13: Business development | E13: 13172.16 | F13: AUQ | G13: 45708 | H13: AP Accruals | I13: 2101-ASTIR00 | K13: Accrued from 2024: STCF Gold S | L13: 2101 | M13: STIRLINGS TO COAST FARMERS | Q13: =ABS(E13) -> 13172.16
A14: AU001 | B14: AU032046 | C14: 5160011000 | D14: Business development | E14: 9330.28 | F14: AUQ | G14: 45664 | H14: AP Accruals | I14: RABO2025/6-ASOLU01 | K14: RaboTruck Angus Expo | L14: RABO2025/6 | M14: SOLUTION ENTERTAINMENT | Q14: =ABS(E14) -> 9330.28
A15: AU001 | B15: AU032046 | C15: 5160011000 | D15: Business development | E15: 9330.28 | F15: AUQ | G15: 45664 | H15: AP Accruals | I15: RABO2025/6-ASOLU01 | K15: RaboTruck FNQ FDs | L15: RABO2025/6 | M15: SOLUTION ENTERTAINMENT | Q15: =ABS(E15) -> 9330.28
A16: AU001 | B16: AU032046 | C16: 5160011000 | D16: Business development | E16: 9330.28 | F16: AUQ | G16: 45664 | H16: AP Accruals | I16: RABO2025/6-ASOLU01 | K16: RaboTruck Taroom Show | L16: RABO2025/6 | M16: SOLUTION ENTERTAINMENT | Q16: =ABS(E16) -> 9330.28
A17: AU052 | B17: AU032046 | C17: 5160011000 | D17: Business development | E17: 9100.01 | F17: AUQ | G17: 45744 | H17: CCMS | I17: EllisT-Offshore Meals & Lodgin | J17: Griffith Client Dinner - with RaboResearch, Ben Picton | O17: LA SCALA RESTAURANT | Q17: =ABS(E17) -> 9100.01 | S17: ME | T17: Y | U17: =B17 -> AU032046 | V17: =E17 -> 9100.01
A18: AU001 | B18: AU032046 | C18: 5160011000 | D18: Business development | E18: 7683.76 | F18: AUQ | G18: 45698 | H18: AP Accruals | I18: INV-0035-AGROW01 | K18: GROWQ Sponsorship Fee | L18: INV-0035 | M18: GROWQ ASSOCIATION INC | Q18: =ABS(E18) -> 7683.76
A19: AU001 | B19: AU032051 | C19: 5160011000 | D19: Business development | E19: 5499.65 | F19: AUQ | G19: 45664 | H19: AP Accruals | I19: INV-0215-ADUAL00 | K19: Farm to Fork Deposit dinner | L19: INV-0215 | M19: DUAL ENTERTAINMENT PTY LTD | Q19: =ABS(E19) -> 5499.65 | S19: ME | T19: Y | U19: =B19 -> AU032051 | V19: =E19 -> 5499.65
A20: AU001 | B20: AU032046 | C20: 5160011000 | D20: Business development | E20: 5488.4 | F20: AUQ | G20: 45677 | H20: AP Accruals | I20: 00000412-ANORT51 | K20: Darwin Branch sponsorship 2025 | L20: 412 | M20: NORTHERN TERRITORY FARMERS ASSOCIATION | Q20: =ABS(E20) -> 5488.4
A21: AU001 | B21: AU032046 | C21: 5160011000 | D21: Business development | E21: 4989.45 | F21: AUQ | G21: 45706 | H21: AP Accruals | I21: 2063-ASHAN05 | K21: North East Dairy Business grou | L21: 2063 | M21: SHANNON FARM CONSULTING | Q21: =ABS(E21) -> 4989.45
A22: AU001 | B22: AU032046 | C22: 5160011000 | D22: Business development | E22: 4390.72 | F22: AUQ | G22: 45677 | H22: AP Accruals | I22: 610-AGIPP00 | K22: Gippsland Red Meat Conference | L22: 610 | M22: GIPPSLAND AGRICULTURAL GROUP (182920421) | Q22: =ABS(E22) -> 4390.72
A23: AU001 | B23: AU032046 | C23: 5160011000 | D23: Business development | E23: 4390.72 | F23: AUQ | G23: 45677 | H23: AP Accruals | I23: 610-AGIPP02 | K23: Gippsland Red Meat Conference | L23: 610 | M23: GIPPSLAND AGRICULTURAL GROUP INC | Q23: =ABS(E23) -> 4390.72
A24: AU001 | B24: AU032046 | C24: 5160011000 | D24: Business development | E24: -4390.72 | F24: AUQ | G24: 45679 | H24: AP Accruals | I24: 610-AGIPP00 | K24: Gippsland Red Meat Conference | L24: 610 | M24: GIPPSLAND AGRICULTURAL GROUP (182920421) | Q24: =ABS(E24) -> 4390.72
A25: AU001 | B25: AU032046 | C25: 5160011000 | D25: Business development | E25: 4379.74 | F25: AUQ | G25: 45705 | H25: AP Accruals | I25: 2774-ATURN01 | K25: Sunscreen promo items for CC i | L25: 2774 | M25: TURNKEY PROMOTIONS | Q25: =ABS(E25) -> 4379.74
A26: AU001 | B26: AU032046 | C26: 5160011000 | D26: Business development | E26: 4008.73 | F26: AUQ | G26: 45706 | H26: AP Accruals | I26: INV1287-ATHEF04 | K26: World Angus Forum - Presenter | L26: INV1287 | M26: THE FINANCIAL BLOKE GROUP PTY LTD | Q26: =ABS(E26) -> 4008.73
A27: AU052 | B27: AU032046 | C27: 5160011000 | D27: Business development | E27: 3264 | F27: AUQ | G27: 45734 | H27: CCMS | I27: TierneyA-Default Licensee Merc | J27: NTCA Reg Fee x 4 + credit card fee | O27: AAP Events | Q27: =ABS(E27) -> 3264
A28: AU001 | B28: AU032046 | C28: 5160011000 | D28: Business development | E28: 3128.39 | F28: AUQ | G28: 45726 | H28: AP Accruals | I28: 000425990-AUNIV02 | K28: Feeder steer school 2.0 comerc | L28: 425990 | M28: UNIVERSITY OF NEW ENGLAND | Q28: =ABS(E28) -> 3128.39
A29: AU001 | B29: AU032046 | C29: 5160011000 | D29: Business development | E29: 3017.12 | F29: AUQ | G29: 45664 | H29: AP Accruals | I29: INV-905-ACAFE00 | K29: Christmas party for clients | L29: INV-905 | M29: CAFE GRAY | Q29: =ABS(E29) -> 3017.12 | S29: ME | T29: Y | U29: =B29 -> AU032046 | V29: =E29 -> 3017.12
A30: AU001 | B30: AU032046 | C30: 5160011000 | D30: Business development | E30: 3000 | F30: AUQ | G30: 45720 | H30: AP Accruals | I30: INV-1109-ASOUT23 | K30: SE Field Days sponorship | L30: INV-1109 | M30: SOUTH EAST FIELD DAYS | Q30: =ABS(E30) -> 3000
A31: AU001 | B31: AU032046 | C31: 5160011000 | D31: Business development | E31: 2893.88 | F31: AUQ | G31: 45734 | H31: AP Accruals | I31: 00003390-AWHAR00 | K31: NTCA Catering for pre conf eve | L31: 3390 | M31: WHARF ONE FOOD & WINE IL LIDO BAR PIZZA | Q31: =ABS(E31) -> 2893.88 | S31: Accept business - part of seminar
A32: AU001 | B32: AU032046 | C32: 5160011000 | D32: Business development | E32: 2870 | F32: AUQ | G32: 45674 | H32: AP Accruals | I32: INV-2002-AWARR | K32: Local branch event RaboTruck M | L32: INV-2002 | M32: WARROO PARTNERSHIP | Q32: =ABS(E32) -> 2870
A33: AU001 | B33: AU032046 | C33: 5160011000 | D33: Business development | E33: 2802.22 | F33: AUQ | G33: 45706 | H33: AP Accruals | I33: INV-030721-ACENT02 | K33: Events Air invoice | L33: INV-030721 | M33: CENTIUM SOFTWARE PTY LTD TA EVENTSAIR | Q33: =ABS(E33) -> 2802.22
A34: AU001 | B34: AU032046 | C34: 5160011000 | D34: Business development | E34: 2744.2 | F34: AUQ | G34: 45698 | H34: AP Accruals | I34: I-250108-003-ABRAN06 | K34: Sponsorship Fee | L34: I-250108-003 | M34: AUSTRALIAN BRANGUS CATTLE ASSOCIATION | Q34: =ABS(E34) -> 2744.2
A35: AU001 | B35: AU032051 | C35: 5160011000 | D35: Business development | E35: 2692.96 | F35: AUQ | G35: 45701 | H35: AP Accruals | I35: INV-10370_AU_202411-ATRAC01 | K35: Tracksuit invoice (difference | L35: INV-10370_AU_20241101 | M35: TRACKSUIT LIMITED | Q35: =ABS(E35) -> 2692.96
A36: AU001 | B36: AU032046 | C36: 5160011000 | D36: Business development | E36: 2500 | F36: AUQ | G36: 45691 | H36: AP Accruals | I36: 1000-ABENE01 | K36: Beneath The Brim Sponsorship b | L36: 1000 | M36: A DAUGHTERS WAY LTD TA BENEATH THE BRIM | Q36: =ABS(E36) -> 2500
A37: AU001 | B37: AU032046 | C37: 5160011000 | D37: Business development | E37: 2195.36 | F37: AUQ | G37: 45701 | H37: AP Accruals | I37: INV-0689-AMONA08 | K37: 2025 Sponsorship of Monaro Far | L37: INV-0689 | M37: MONARO FARMING SYSTEMS | Q37: =ABS(E37) -> 2195.36
A38: AU001 | B38: AU032046 | C38: 5160011000 | D38: Business development | E38: 2195.36 | F38: AUQ | G38: 45734 | H38: AP Accruals | I38: PSI-000380-AMURR07 | K38: Murray Dairy Limited - Goulbu | L38: PSI-000380 | M38: MURRAY DAIRY LIMITED | Q38: =ABS(E38) -> 2195.36
A39: AU052 | B39: AU030619 | C39: 5160011000 | D39: Business development | E39: 2180 | F39: AUQ | G39: 45740 | H39: CCMS | I39: BriginshawZ-Offshore Meals & L | J39: Woolorama plater supplies. Noting difference between invoice and payment is card fees to visa/ maste | O39: NARROGIN FRUIT MARKET | Q39: =ABS(E39) -> 2180
A40: AU052 | B40: AU032046 | C40: 5160011000 | D40: Business development | E40: 2035.76 | F40: AUQ | G40: 45664 | H40: AP Accruals | I40: 00018230-ARURA00 | K40: Agfest Tax Invoice - Site Paym | L40: 18230 | M40: RURAL YOUTH ORGANISATION OF TASMANIA INC | Q40: =ABS(E40) -> 2035.76
...

Sheet PR exp
A1: Account Number | C1: =Summary!A17 -> 5160999000
A2: Account Name | C2: =Summary!B17 -> Public relations | F2: Notes:
A3: GL Total | C3: 11669.68 | F3: No entertainment expenses included and all tax deductible
A4: Per TB | C4: =SUM(E:E) -> 11669.68 | T4: AU001 | V4: =SUMIF($A$10:$A$23974,"AU001",V9:V23973) -> 0
A5: Variance | C5: =C3-C4 -> 0 | T5: AU052 | V5: =SUMIF($A$10:$A$23975,"AU052",V9:V23974) -> 0
AD6: Income tax purposes
A7: BUSINESS_UNIT_CODE | B7: OPERATING_UNIT_CODE | C7: ACCOUNT_CODE | D7: DESCRIPTION | E7: BASE_AMOUNT | F7: BASE_CURRENCY_CODE | G7: JOURNAL_DATE | H7: DESCR | I7: LINE_DESCR | J7: PURPOSE | K7: INVOICE_DESCR | L7: INVOICE_ID | M7: VENDOR_NAME | N7: EMPLOYEE_NAME | O7: CHARGE_DESCRIPTION | Q7: ABS | R7: Search Terms | S7: Tax Description | T7: ME? Y/N | U7: OU | V7: ME $ | W7: Not ME but other type of FB Y/N | X7: Not ME but other type of FB ==> $ | Y7: Nets to Nil in GL accts | Z7: s58P M&I or Bus Exp - notFB | AA7: ME | AB7: Car FB - addn op costs | AC7: CP Exp FB | AD7: Capital expenditure | AE7: No FBT and not ded | AF7: Additional Comments
A8: AU001 | B8: AU032045 | C8: 5160999000 | D8: Public relations | E8: 11300.44 | F8: AUQ | G8: 45734 | H8: AP Accruals | I8: INV-22088-ASTEE00 | K8: Streem subscription | L8: INV-22088 | M8: STREEM PTY LTD | Q8: =ABS(E8) -> 11300.44 | S8: subscription - OK
A9: AU052 | B9: AU032045 | C9: 5160999000 | D9: Public relations | E9: 15.67 | F9: AUQ | G9: 45674 | H9: CCMS | I9: SHAWD-Default Licensee Merchan | J9: publication on markets and implications of Tump tariff issues | O9: SYD201 | Q9: =ABS(E9) -> 15.67 | S9: OK
